Workbook

Sheet 초입
A1: 연번 | B1: 소속교 | C1: 학급유형 | D1: 학년 | E1: 성명 | F1: 성별 | G1: 생년월일 | H1: 선정배치 | J1: 장애유형(유형변경 파란색) | M1: 주소 | N1: 최근거리교 | R1: 희망교 | AD1: 연락처 | AF1: 특수학교(유치부) | AO1: 검사결과 | AP1: 특이사항 | AQ1: 접수완료 | AR1: 2검 (원본 완성 기준)
H2: 기존 | I2: 신규 | J2: 특수교육법 | K2: 장애인복지법 | N2: 학교명 | O2: 배치유형 | P2: 통학방법 | Q2: 거리(km) | R2: 1희망교 | V2: 2희망교 | Z2: 3희망교 | AF2: 1희망 | AI2: 2희망 | AL2: 3희망
J3: 영역 | K3: 영역 | L3: 정도 | R3: 학교명 | S3: 배치유형 | T3: 통학방법 | U3: 거리(km) | V3: 학교명 | W3: 배치유형 | X3: 통학방법 | Y3: 거리(km) | Z3: 학교명 | AA3: 배치유형 | AB3: 통학방법 | AC3: 거리(km) | AD3: 보호자 | AE3: 담당교사 | AF3: 지역 | AG3: 학교명 | AH3: 학급유형 | AI3: 지역 | AJ3: 학교명 | AK3: 학급유형 | AL3: 지역 | AM3: 학교명 | AN3: 학급유형
A4: 1 | B4: 시립동구어린이집 | D4: 3 | E4: 김연성 | F4: 남 | G4: 2020.02.25. | I4: O | J4: 의사소통장애 (지적장애 범주) | M4: 경기도 구리시 경춘로276번길 21, 107동 1002호(구리역한양수자인) | N4: 구리초등학교 | O4: 특수학급 | Q4: 0.1 | R4: 구리초등학교 | S4: 특수학급 | U4: 0.1 | V4: 구지초등학교 | W4: 특수학급 | Y4: 1.2 | Z4: 동구초등학교 | AA4: 특수학급 | AC4: 1.4 | AD4: 010-8865-6065 | AO4: ※심리평가보고서(2026.3.12.) □ K-WPPSI-Ⅳ: 전체IQ 53(언어이해 50, 시공간 79, 유동추론 66, 작업기억 61, 처리속도 64/매우 낮음) □ 사회성숙도: SA 4세7개월, SQ 78.33(경계선) □ CARS: 22.5점 □ 적응행동검사: 표준점수 70(저조한 수준) | AP4: *검사결과 지적장애 범주. 신규지만 지적장애로 유형변경 | AQ4: 완료 | AR4: 완료
A5: 2 | B5: 없음 | E5: 김주연 | F5: 여 | G5: 2020.10.10. | I5: O | J5: 지적장애 | K5: 지적·자폐성장애 | L5: 중증 | M5: 현: 경기도 구리시 건원대로 92, 115동 1405호(인창동 주공아파트) 이사: 경기도 구리시 수택동 444-6 | N5: 부양초등학교 | O5: 특수학급 | Q5: 0.454 | R5: 부양초등학교 | S5: 특수학급 | U5: 0.454 | V5: 백문초등학교 | W5: 특수학급 | Y5: 1.2 | Z5: 토평초등학교 | AA5: 특수학급 | AC5: 1.2 | AD5: 010-8999-2232 | AO5: □ 복지카드: 지적,자폐성장애 중증(~2032.03.02.) | AP5: 7월30일 거주지 이전 / 대중교통 이용 / 현 주소 기준으로 거리 작성됨 / 자차기준 토평, 백문, 도림, 교문 모두 1.1~1.2km임 / 1순위 안되면 참고 | AQ5: 완료 | AR5: 완료
A6: 3 | B6: 하늘숲어린이집 | D6: 3 | E6: 양서율 | F6: 여 | G6: 2020.01.26. | I6: O | J6: 자폐성장애 | K6: 자폐성장애 | L6: 중증 | M6: 경기도 남양주시 오남읍 양지로46번길 130, 102동 503호 | N6: 오남초등학교 | O6: 특수학급 | Q6: 1.4 | R6: 오남초등학교 | S6: 특수학급 | U6: 1.4 | V6: 남양주양지초등학교 | W6: 특수학급 | Y6: 1.2 | Z6: 양오초등학교 | AA6: 특수학급 | AC6: 1.8 | AD6: 010-2228-7151 | AF6: 구리남양주 | AG6: 경은학교 | AH6: 특수학교 | AI6: 구리남양주 | AJ6: 복합특수학급 신설 | AK6: 복합특수학급 | AL6: 의정부 | AM6: 송민학교 | AN6: 특수학교 | AO6: □ 복지카드: 자폐성장애 중증(~2028.09.28.) | AQ6: 완료 | AR6: 완료
A7: 4 | B7: 시립토평마을어린이집 | D7: 3 | E7: 신주원 | F7: 남 | G7: 2020.08.16. | I7: O | J7: 자폐성장애 | K7: 자폐성장애 | L7: 중증 | M7: 경기도 구리시 검배로72번길 89, 3층 | N7: 부양초등학교 | O7: 특수학급 | Q7: 0.45 | R7: 부양초등학교 | S7: 특수학급 | U7: 0.45 | V7: 수택초등학교 | W7: 특수학급 | Y7: 1.1 | Z7: 교문초등학교 | AA7: 특수학급 | AC7: 1.1 | AD7: 010-3003-1574 | AO7: □ 복지카드: 자폐성장애 중증(~2032.01.14.) | AP7: 도보 기준 작성함. 자동차기준, 교문1.2 / 토평1.1 / 수택 1.9 | AQ7: 완료 | AR7: 완료
A8: 5 | B8: 시립토평마을어린이집 | D8: 3 | E8: 김서하 | F8: 남 | G8: 2020.07.15. | I8: O | J8: 청각장애 | K8: 청각장애 | L8: 중증 | M8: 경기도 구리시 검배로 142 204동, 1104호(SK신일아파트) | N8: 수택초등학교 | O8: 특수학급 | Q8: 0.237 | R8: 수택초등학교 | S8: 특수학급 | U8: 0.237 | V8: 수택초등학교 | W8: 일반학급 | Y8: 0.237 | AD8: 010-9133-1701 | AO8: □ 복지카드: 청각장애 중증(유효기한 없음) | AP8: 쌍둥이(김루하)와 동일교 배치 희망, 등본제출함 | AQ8: 완료 | AR8: 완료
A9: 6 | B9: 시립토평마을어린이집 | D9: 3 | E9: 김루하 | F9: 남 | G9: 2020.07.15. | I9: O | J9: 청각장애 | K9: 청각장애 | L9: 경증 | M9: 경기도 구리시 검배로 142 204동, 1104호(SK신일아파트) | N9: 수택초등학교 | O9: 특수학급 | Q9: 0.237 | R9: 수택초등학교 | S9: 특수학급 | U9: 0.237 | V9: 수택초등학교 | W9: 일반학급 | Y9: 0.237 | AD9: 010-9133-1701 | AO9: □ 복지카드: 청각장애 경증(~2028.07.28) | AP9: 쌍둥이(김서하)와 동일교 배치 희망, 등본제출함 | AQ9: 완료 | AR9: 완료
A10: 7 | B10: 화도어린이집 | D10: 3 | E10: 김로건 | F10: 남 | G10: 2020.10.12. | I10: O | J10: 자폐성장애 | K10: 자폐성장애 | L10: 중증 | M10: 경기도 남양주시 화도읍 북한강로 1503번길2, 2층 | N10: 금남초등학교 | O10: 일반학급 | Q10: 0.05 | R10: 금남초등학교 | S10: 일반학급 | U10: 0.05 | AD10: 010-5350-1095 | AO10: □ 복지카드: 자폐성장애 중증(~2029.10.10.) | AQ10: 완료 | AR10: 완료
A11: 8 | B11: 장현새싹어린이집 | D11: 3 | E11: 오태희 | F11: 여 | G11: 2020.04.17. | I11: O | J11: 발달지체 | M11: 경기도 남양주시 진접읍 장현로 87번길 9, 남양주택 라동 403호 | N11: 장현초등학교 | O11: 특수학급 | Q11: 0.1 | R11: 장현초등학교 | S11: 특수학급 | U11: 0.1 | V11: 장현초등학교 | W11: 일반학급 | Y11: 0.1 | AD11: 010-2895-1244 | AO11: 진단평가 필요 | AQ11: 완료 | AR11: 완료
A12: 9 | B12: 구리시립갈매어린이집 | D12: 3 | E12: 이인규 | F12: 남 | G12: 2020.11.12. | I12: O | J12: 의사소통장애 (지적장애 범주이나, 검사결과 신뢰X, 발달지체?, 심층관찰 시 자폐 성향) | M12: 경기도 남양주시 퇴계원읍 도제원로 89-1, 102동 301호(삼성하이츠) | N12: 퇴계원초등학교 | O12: 특수학급 | Q12: 1.1 | R12: 퇴계원초등학교 | S12: 특수학급 | U12: 1.1 | V12: 도제원초등학교 | W12: 특수학급 | Y12: 1.1 | Z12: 내양초등학교 | AA12: 특수학급 | AC12: 2.4 | AD12: 010-4397-1648 | AF12: 구리남양주 | AG12: 경은학교 | AH12: 특수학교 | AI12: 구리남양주 | AJ12: 복합특수학급 신설 | AK12: 복합특수학급 | AO12: ※2026년 7월 9일 검사 실시 □K-WPPSI-IV: 전체IQ 40 (언어이해 45, 시공간 79, 유동추론 45, 작업기억 45, 처리속도 45/매우 낮음) □적응행동검사: 표준점수 54(상당히 저조한 수준) □사회성숙도: SA 1세 11개월, SQ 35.30(중등도) | AQ12: 완료 | AR12: 완료
A13: 10 | B13: 다산아이사랑어린이집 | D13: 3 | E13: 정이안 | F13: 여 | G13: 2020.08.10. | I13: O | J13: 자폐성장애 | K13: 발급중 | M13: 경기도 남양주시 다산중앙로82번길 12, 5302동 2502호(다산자연앤 이편한세상 3차) | N13: 다산새봄초등학교 | O13: 특수학급 | Q13: 0.385 | R13: 다산새봄초등학교 | S13: 특수학급 | U13: 0.385 | V13: 다산가람초등학교 | W13: 특수학급 | Y13: 0.878 | Z13: 남양주다산초등학교 | AA13: 특수학급 | AC13: 1.2 | AD13: 010-6641-1224 | AO13: ※ 6월 중 복지카드 발급 예정 / 7월중말로 연기 | AP13: *비장애 쌍둥이와 동일교 배치 희망 *2027년 1~2월 중 이사 예정, 그러나 이사 예정지와 입주일이 불명확하여 10월 말까지 계약서가 나오면 별도 연락주기로 함. | AQ13: 미흡 | AR13: 미흡
A14: 11 | B14: 시립호평어린이집 | D14: 3 | E14: 김다원 | F14: 남 | G14: 2020.08.09. | I14: O | J14: 청각장애 | K14: 청각장애 | L14: 중증 | M14: 경기도 남양주시 평내로 104, 1905동 503호 | N14: 남양주백봉초등학교 | O14: 특수학급 | Q14: 0.159 | R14: 남양주백봉초등학교 | S14: 특수학급 | U14: 0.159 | V14: 남양주백봉초등학교 | W14: 일반학급 | Y14: 0.159 | AD14: 010-9220-1146 | AO14: □ 복지카드: 청각장애 중증(유효기한 없음) | AQ14: 완료 | AR14: 완료
A15: 12 | B15: 하람어린이집 | D15: 3 | E15: 김하건 | F15: 남 | G15: 2020.07.16. | I15: O | J15: 자폐성장애 | K15: 자폐성장애 | L15: 중증 | M15: 경기도 구리시 산마루로 46, 409동 1302호 | N15: 갈매초등학교 | O15: 특수학급 | Q15: 0.649 | R15: 갈매초등학교 | S15: 특수학급 | U15: 0.649 | V15: 산마루초등학교 | W15: 특수학급 | Y15: 0.433 | Z15: 한별초등학교 | AA15: 특수학급 | AC15: 2.5 | AD15: 010-4714-7728 | AO15: □ 복지카드: 자폐성장애 중증(~2029.06.21.) | AQ15: 완료 | AR15: 완료
A16: 13 | B16: 오남복지어린이집 | D16: 3 | E16: 이지오 | F16: 남 | G16: 2020.04.23. | I16: O | J16: 자폐성장애 | K16: 자폐성장애 | L16: 중증 | M16: 경기도 남양주시 오남읍 진건오남로759번길 5, 101동 207호(보영아파트) | N16: 오남초등학교 | O16: 특수학급 | Q16: 0.837 | R16: 오남초등학교 | S16: 특수학급 | U16: 0.837 | V16: 남양주양지초등학교 | W16: 특수학급 | Y16: 0.97 | Z16: 양오초등학교 | AA16: 특수학급 | AC16: 1.8 | AD16: 010-8899-3796 | AF16: 구리남양주 | AG16: 복합특수학급 신설 | AH16: 복합특수학급 | AO16: □ 복지카드: 자폐성장애 중증(~2032.02.26.) | AQ16: 완료 | AR16: 완료
A17: 14 | B17: 시립미사어린이집 | D17: 3 | E17: 한준영 | F17: 남 | G17: 2020.04.07. | I17: O | J17: 지적장애 (중도중복 가능) | K17: 지적·뇌병변장애 | L17: 중증 | M17: 경기도 남양주시 천마산로12번길 19-10, 101동 404호(메종드힐) | N17: 호평초등학교 | O17: 특수학급 | Q17: 0.935 | R17: 호평초등학교 | S17: 특수학급 | U17: 0.935 | V17: 판곡초등학교 | W17: 특수학급 | Y17: 1.1 | Z17: 구룡초등학교 | AA17: 특수학급 | AC17: 1.4 | AD17: 010-5219-0736 | AF17: 구리남양주 | AG17: 경은학교 | AH17: 특수학교 | AI17: 의정부 | AJ17: 송민학교 | AK17: 특수학교 | AO17: □ 복지카드: 지적·뇌병변장애 중증(~2027.11.09.) □ 장애인증명서 지적(심한), 뇌병변(심한) 제출 | AP17: 특수학교 입학 불가 시 유예 희망 | AQ17: 완료 | AR17: 완료
A18: 15 | B18: 시립진접어린이집 | D18: 3 | E18: 박준상 | F18: 남 | G18: 2020.06.02. | I18: O | J18: 자폐성장애 | K18: 자폐성장애 | L18: 중증 | M18: 경기도 남양주시 진접읍 금강로 1530-14, 102동 301호(진접하우스토리) | N18: 장승초등학교 | O18: 특수학급 | Q18: 0.675 | R18: 장승초등학교 | S18: 특수학급 | U18: 0.675 | V18: 해밀초등학교 | W18: 특수학급 | Y18: 1.4 | Z18: 진접초등학교 | AA18: 특수학급 | AC18: 1.4 | AD18: 010-8963-3676 | AO18: □ 복지카드: 자폐성장애 중증(~2032.05.20.) | AP18: *장승초에 재학 중인 장애 형제와 동일교 배치 희망 *형제 재학증명서 추가 제출 전화 요청하고 받았음 | AQ18: 완료 | AR18: 완료
A19: 16 | B19: 시립다산아이편한어린이집 | D19: 3 | E19: 윤수아 | F19: 여 | G19: 2020.08.13. | I19: O | J19: 자폐성장애 | K19: 자폐성장애 | L19: 중증 | M19: 경기도 남양주시 다산중앙로 82번안길 74, 605동 305호(다산푸르지오) | N19: 다산별빛초등학교 | O19: 특수학급 | Q19: 0.515 | R19: 다산별빛초등학교 | S19: 특수학급 | U19: 0.545 | V19: 금교초등학교 | W19: 특수학급 | Y19: 0.209 | Z19: 남양주양정초등학교 | AA19: 특수학급 | AC19: 0.969 | AD19: 010-4760-2025 | AO19: □ 복지카드: 자폐성장애 중증(~2032.02.16.) | AQ19: 완료 | AR19: 완료
A20: 17 | B20: 무지개유치원 | D20: 3 | E20: 김서진 | F20: 남 | G20: 2020.11.12. | I20: O | J20: 발달지체 | M20: 경기도 남양주시 덕소로 2번길 39, 덕소강변삼익@ 108동 1502호 | N20: 덕소초등학교 | O20: 특수학급 | Q20: 0.99 | R20: 덕소초등학교 | S20: 특수학급 | U20: 0.99 | V20: 도곡초등학교 | W20: 특수학급 | Y20: 1.2 | Z20: 예봉초등학교 | AA20: 특수학급 | AC20: 1.9 | AD20: 010-4745-1367 | AO20: 26.6.26에 병원에서 윕시 검사 실시, 검사결과 유치원으로 제출 안내완 사회성숙도 추가실시 | AP20: 의뢰서 수정공문 요청. / 배치유형, 등본확인 / 6.26에 외부 평가 실시함 / 양식 수정본과 함께 결과 보고서 공문으로 받아야함 | AQ20: 미흡 | AR20: 미흡
A21: 18 | B21: 남양주신촌초등학교병설유치원 | C21: 특수학급 | D21: 3 | E21: 강민찬 | F21: 남 | G21: 2020.01.08. | H21: O | J21: 발달지체 (자폐성장애 가능) | M21: 경기도 남양주시 평내로 89, 1302동 2003호 | N21: 장내초등학교 | O21: 특수학급 | Q21: 0.36 | R21: 장내초등학교 | S21: 특수학급 | U21: 0.36 | V21: 남양주신촌초등학교 | W21: 특수학급 | Y21: 0.43 | Z21: 백봉초등학교 | AA21: 특수학급 | AC21: 0.55 | AD21: 010-6239-9038 | AO21: ※심리평가보고서(2026.5.14.) □K-WPPSI-IV: 전체IQ 40 (언어이해 45, 시공간 46, 유동추론 45, 작업기억 45, 처리속도 45/매우낮음) □사회성숙도: SA 2세 4개월, SQ 38.07(매우낮음) □K-CARS-Ⅱ(ST): 총점 35점(경도에서 중등도 수준의 자폐 관련 행동) -CBCL, 적응행동검사 추기실시? | AP21: 발달지체로 작성했지만 자폐성장애로 유형 변경 가능성 인지 진단서: 소아기 자폐증(임상적 추정) | AQ21: 완료 | AR21: 완료
A22: 19 | B22: 시립토평마을어린이집 | D22: 3 | E22: 박규빈 | F22: 남 | G22: 2020.07.17. | I22: O | J22: 자폐성장애 | K22: 자폐성장애 | L22: 중증 | M22: 경기도 남양주시 다산중앙로146번길7, 2202동 1101호(다산동, 다산롯데캐슬) | N22: 남양주다산초등학교 | O22: 특수학급 | Q22: 0.307 | R22: 남양주다산초등학교 | S22: 특수학급 | U22: 0.307 | V22: 다산새봄초등학교 | W22: 특수학급 | Y22: 0.869 | Z22: 다산하늘초등학교 | AA22: 특수학급 | AC22: 1 | AD22: 010-7320-1455 | AF22: 구리남양주 | AG22: 경은학교 | AH22: 특수학교 | AI22: 구리남양주 | AJ22: 복합특수학급 신설 | AO22: □ 복지카드: 자폐성장애 중증(~2032.06.19.) | AP22: 도보 통학 기준 / 2,3희망교 바뀜. | AQ22: 완료 | AR22: 완료
A23: 20 | B23: 시립와부어린이집 | D23: 3 | E23: 이아윤 | F23: 여 | G23: 2020.05.28 | I23: O | J23: 자폐성장애 | K23: 자폐성장애 | L23: 중증 | M23: 경기도 남양주시 와부읍 덕소로 150, 강변현대아파트 102동 1304호 | N23: 남양주도곡초등학교 | O23: 특수학급 | Q23: 0.359 | R23: 남양주도곡초등학교 | S23: 특수학급 | U23: 0.359 | V23: 덕소초등학교 | W23: 특수학급 | Y23: 0.98 | Z23: 예봉초등학교 | AA23: 특수학급 | AC23: 1.8 | AD23: 010-4188-6163 | AO23: □ 복지카드: 자폐성장애 중증(2032. 07. 20.) | AP23: 복지카드 추가 제출 받아야 / 완료 | AQ23: 미흡 | AR23: 완료
A24: 21 | B24: 동그라미어린이집 | D24: 3 | E24: 박태연 | F24: 여 | G24: 2020.06.25. | I24: O | J24: 지적장애 | M24: 경기도 남양주시 화도읍 비룡로 186, 110동 304호 | N24: 가곡초등학교 | O24: 특수학급 | Q24: 2.2 | R24: 가곡초등학교 | S24: 특수학급 | U24: 2.2 | V24: 화도초등학교 | W24: 특수학급 | Y24: 1.3 | Z24: 남양주송라초등학교 | AA24: 특수학급 | AC24: 2.1 | AD24: 010-5092-4027 | AO24: ※심리평가보고서 □ 지능검사 결과(08.04. 결과지 수령 예정), □ 사회성숙도: SA 3세 11개월, SQ 65.1(경도) □ 적응행동검사: 표준점수 71 (저조한 수준) ※심리평가보고서(2025.7.1.)(CA 60개월시점) □PRES: 수용언어 70점 (3세6개월/2%ile) , 표현언어 81.67점 (4세 1 개월/6%ile) □U-TAP2: 자음정확도 63.83% (<1%ile/중도) | AP24: 지능검사 결과 8월초 추가 예정 | AQ24: 미흡 | AR24: 미흡
A25: 22 | B25: 다산자이폴라리스어린이집 | D25: 3 | E25: 박재하 | F25: 남 | G25: 2020.09.03. | I25: O | J25: 자폐성장애 | K25: 자폐성장애 | L25: 중증 | M25: 경기도 남양주시 다산순환로 242, 다산자이폴라리스 1404동 603호 | N25: 다산하늘초등학교 | O25: 특수학급 | Q25: 0.57 | R25: 다산하늘초등학교 | S25: 특수학급 | U25: 0.57 | V25: 남양주다산초등학교 | W25: 특수학급 | Y25: 1.1 | Z25: 다산새봄초등학교 | AA25: 특수학급 | AC25: 1.8 | AD25: 010-3074-5250 | AO25: □ 복지카드: 자폐성장애 중증(~2032.06.08.) | AQ25: 완료 | AR25: 완료
A26: 23 | B26: 화도어린이집 | D26: 3 | E26: 조민채 | F26: 여 | G26: 2020.06.10. | I26: O | J26: 지적장애 | K26: 지적뇌병변장애 | L26: 중증 | M26: 경기도 남양주시 화도읍 수레로 1105-27, 204-804 | N26: 차산초등학교 | O26: 특수학급 | Q26: 0.4 | R26: 차산초등학교 | S26: 특수학급 | U26: 0.4 | V26: 창현초등학교 | W26: 특수학급 | Y26: 1.6 | Z26: 마석초등학교 | AA26: 특수학급 | AC26: 2.1 | AD26: 010-8485-8640 | AO26: □ 복지카드: 지적뇌병변장애 중증(~2026.10.15.) | AP26: 장애인증명서 추가 제출 예정 / 지적,뇌병변에서 지적으로 변경 예정 / 7월중 이메일로 예정. 문자 보냄. / 들어옴 | AQ26: 미흡 | AR26: 완료
A27: 24 | B27: 안델센어린이집 | D27: 3 | E27: 홍나예 | F27: 여 | G27: 2020.02.16. | I27: O | J27: 지적장애 (발달지체로 신청) | M27: 경기도 구리시 안골로20번길 8-17, 101호 | N27: 교문초등학교 | O27: 특수학급 | Q27: 0.227 | R27: 교문초등학교 | S27: 특수학급 | U27: 0.227 | V27: 도림초등학교 | W27: 특수학급 | Y27: 0.45 | Z27: 백문초등학교 | AA27: 특수학급 | AC27: 0.9 | AD27: 010-6622-6482 | AO27: ※2026년 7월 9일 검사 실시 □K-WISC-V: 전체IQ 48(언어이해 50, 시공간 70, 유동추론 60, 작업기억 53, 처리속도 55/매우 낮음) □적응행동검사: 표준점수 70(저조한 수준) □사회성숙도: SA 3세 0개월, SQ 47.39(중등도) | AQ27: 완료 | AR27: 완료
A28: 25 | B28: 진접어린이집 | D28: 3 | E28: 박서준 | F28: 남 | G28: 2020.12.02. | I28: O | J28: 발달지체 | M28: 경기도 남양주시 진접읍 진벌로 78-17 진하우스 나동301호 | N28: 광릉초등학교 | O28: 특수학급 | Q28: 0.654 | R28: 광릉초등학교 | S28: 특수학급 | U28: 0.654 | V28: 부평초등학교 | W28: 특수학급 | Y28: 2.2 | Z28: 장승초등학교 | AA28: 특수학급 | AC28: 3.3 | AD28: 010-5028-2212 | AO28: ※2026년 3월 3일 검사 실시 □K-WPPSI-IV: 전체IQ 80 (언어이해 71, 시공간 120, 유동추론 69, 작업기억 89, 처리속도 84/평균 이하) *GAI 지표점수 87(평균 이하) □사회성숙도: SA 3세 9개월, SQ 78.8(경계선) □적응행동검사: 표준점수 73(저조한 수준) ※2026년 3월 18일 언어검사 실시(검사당시 5세 3개월) □PRES: 수용언어 31점 (4세4개월/5%ile) , 표현언어 30점 (3세 11 개월/5%ile), 통합언어 50개월(4세 2개월) □U-TAP2: 자음정확도 62.77% (-2SD/조음치료 요망) | AP28: -26년4월 유치 상시 평가결과 활용 -26년4월 상시 부평초병유 배치 후 5월에 바로 취소(방과후 문제) | AQ28: 완료 | AR28: 완료
A29: 26 | B29: 남양주다산유치원 | C29: 특수학급 | D29: 3 | E29: 김기윤 | F29: 남 | G29: 2020.04.27. | H29: O | J29: 자폐성장애 (현 발달지체) | K29: 자폐성·언어장애 | L29: 중증 | M29: 경기도 남양주시 다산중앙로 82번길 15 다산이편한세상 5102동 2303호 | N29: 다산새봄초등학교 | O29: 특수학급 | Q29: 0.44 | R29: 다산새봄초등학교 | S29: 특수학급 | U29: 0.44 | V29: 남양주다산초등학교 | W29: 특수학급 | Y29: 0.88 | Z29: 다산하늘초등학교 | AA29: 특수학급 | AC29: 1.4 | AD29: 010-2606-2684 | AO29: □ 복지카드: 자폐성,언어장애 중증(~2027.08.02.) | AP29: 서식1,2,4 수정 완료 | AQ29: 완료 | AR29: 완료
A30: 27 | B30: 다움어린이집 | D30: 3 | E30: 이예찬 | F30: 남 | G30: 2019.06.24. | I30: O | J30: 자폐성장애 | K30: 자폐성장애 | L30: 심한 | M30: 경기도 남양주시 화도읍 먹갓로 28번길 39-12 신강남 가-102호 | N30: 천마초등학교 | O30: 특수학급 | Q30: 0.12 | R30: 천마초등학교 | S30: 특수학급 | U30: 0.12 | V30: 은솔초등학교 | W30: 특수학급 | Y30: 2.2 | Z30: 남양주송라초등학교 | AA30: 특수학급 | AC30: 2.4 | AD30: 010-3217-6485 | AF30: 구리남양주 | AG30: 경은학교 | AH30: 특수학교 | AI30: 의정부 | AJ30: 송민학교 | AK30: 특수학교 | AL30: 구리남양주 | AM30: 복합특수학급신설 | AO30: □ 장애인증명서: 자폐성장애 심한 | AQ30: 완료 | AR30: 완료
A31: 28 | B31: 남양주덕송초등학교병설유치원 | D31: 3 | E31: 이지효 | F31: 여 | G31: 2020.12.08. | I31: O | J31: 지적장애 | M31: 경기도 남양주시 순화궁로 458-16, 1704동 1204호(별내동, 별내퍼스트포레) | N31: 남양주덕송초등학교 | O31: 특수학급 | Q31: 0.8 | R31: 남양주덕송초등학교 | S31: 특수학급 | U31: 0.8 | V31: 샛별초등학교 | W31: 특수학급 | Y31: 1.5 | Z31: 별가람초등학교 | AA31: 특수학급 | AC31: 1.8 | AD31: 010-9857-2024 | AO31: ※심리평가보고서(2025.12.19.) □K-WPPSI-IV: 전체IQ 59 (언어이해 59, 시공간 82, 유동추론 63, 작업기억 73, 처리속도 78/매우낮음) □사회성숙도: SA 4세 0개월, SQ 80(경계선) □적응행동검사: 표준점수 56(상당히 저조한 수준) | AP31: 적응행동검사 요청 / 장애유형 기재 / 한셀 장애유형 확인 / 수정공문 완료 | AQ31: 완료 | AR31: 완료
A32: 29 | B32: 호평한마음어린이집 | D32: 3 | E32: 정모건 | F32: 남 | G32: 2020.01.15. | I32: O | J32: 발달지체 | M32: 경기도 남양주시 천마산로 65-2 103동 1503호(라인그린아파트) | N32: 호평초등학교 | O32: 특수학급 | Q32: 0.35 | R32: 호평초등학교 | S32: 특수학급 | U32: 0.35 | V32: 판곡초등학교 | W32: 특수학급 | Y32: 1.9 | Z32: 구룡초등학교 | AA32: 특수학급 | AC32: 2.1 | AD32: 010-2045-9252 | AO32: ※심리평가보고서(2025.7.31.) □K-WPPSI-IV: 전체IQ 43 (언어이해 50, 시공간 46, 유동추론 51, 작업기억 79, 처리속도 50/매우낮음) □K-CARS-Ⅱ(ST): 총점 28.5점(증상이 없거나 최소한의 자폐 관련 행동) □K-vineland-Ⅱ: 46(낮음/백분위0.1/%ile) ※심리평가보고서(2025.8.7.) □PRES: 수용언어 25개월 2%ile 미만, 표현언어 23개월 2%ile 미만, 통합언어 24개월, 3년 이상 지연 | AP32: 추후 장애등록&장애유형변경 예정 | AQ32: 완료 | AR32: 완료
A33: 30 | B33: 남양주도담유치원 | C33: 특수학급 | D33: 3 | E33: 윤시우 | F33: 남 | G33: 2020.01.07. | H33: O | J33: 발달지체 | M33: 경기도 남양주시 진접읍 봉현로 36번길 11-1, 105동 506호(삼신아파트) | N33: 장현초등학교 | O33: 특수학급 | Q33: 0.2 | R33: 장현초등학교 | S33: 특수학급 | U33: 0.2 | V33: 화봉초등학교 | W33: 특수학급 | Y33: 2.2 | Z33: 장승초등학교 | AA33: 특수학급 | AC33: 2.5 | AD33: 010-4903-3602 | AF33: 구리남양주 | AG33: 경은학교 | AH33: 특수학교 | AI33: 구리남양주 | AJ33: 복합특수학급신설 | AP33: 장애등록X, 특수학급학생, 최근거리교 확인 및 수정, 한셀시트2 추가 요청 / 수정공문 완료 | AQ33: 완료 | AR33: 완료
A34: 31 | B34: 창현유치원 | C34: 특수학급 | D34: 3 | E34: 권우주 | F34: 남 | G34: 2020.08.23. | H34: O | J34: 발달지체 | M34: 경기도 남양주시 화도읍 녹촌로 51, 신창현두산위브 104동 1101호 | N34: 창현초등학교 | O34: 특수학급 | Q34: 0.589 | R34: 창현초등학교 | S34: 특수학급 | U34: 0.589 | V34: 은솔초등학교 | W34: 특수학급 | Y34: 1.3 | Z34: 마석초등학교 | AA34: 특수학급 | AC34: 1.3 | AD34: 010-4330-0124 | AP34: 서식2 장애명 지체장애로 기재. / 발달지체로 수정공문 들어옴 | AQ34: 완료 | AR34: 완료
A35: 32 | B35: 창현유치원 | C35: 특수학급 | D35: 3 | E35: 이로운 | F35: 남 | G35: 2020.03.07. | H35: O | J35: 자폐성장애 | M35: 경기도 남양주시 화도읍 경춘보학2길 30, 101-1901(라온프라이빗) | N35: 은솔초등학교 | O35: 특수학급 | Q35: 0.25 | R35: 은솔초등학교 | S35: 특수학급 | U35: 0.25 | V35: 남양주송라초등학교 | W35: 특수학급 | Y35: 1.1 | Z35: 창현초등학교 | AA35: 특수학급 | AC35: 1.3 | AD35: 010-8964-0732 | AP35: 희망교 거리 체크 후 바뀜. (창현,마석>송라,창현) | AQ35: 완료 | AR35: 완료
A36: 33 | B36: 창현유치원 | C36: 특수학급 | D36: 3 | E36: 최은우 | F36: 남 | G36: 2020.01.14. | H36: O | J36: 발달지체 | M36: 경기도 남양주시 화도읍 창현로 45, 104동 601호(신창현도뮤토아파트) | N36: 마석초등학교 | O36: 특수학급 | Q36: 0.76 | R36: 마석초등학교 | S36: 특수학급 | U36: 0.76 | V36: 창현초등학교 | W36: 특수학급 | Y36: 0.32 | Z36: 은솔초등학교 | AA36: 특수학급 | AC36: 1.3 | AD36: 010-5555-9213 | AF36: 구리남양주 | AG36: 경은학교 | AH36: 특수학교 | AI36: 구리남양주 | AJ36: 복합특수학급신설 | AL36: 광주하남 | AM36: 성광학교 | AN36: 특수학교 | AP36: 장애유형, 특수학교 희망교 수정 요청 / 최근거리는 창현초이지만, 학구가 마석초등학교임 / 발달지체로 서식1,2 수정공문 들어옴 | AQ36: 완료 | AR36: 완료
A37: 34 | B37: 부양초등학교병설유치원 | C37: 일반학급 | D37: 3 | E37: 서민재 | F37: 남 | G37: 2020.12.07. | H37: O | J37: 발달지체 | M37: 경기도 구리시 체육관로 66 대림한숲@ 105-1407 | N37: 부양초등학교 | O37: 특수학급 | Q37: 0.47 | R37: 부양초등학교 | S37: 특수학급 | U37: 0.47 | V37: 백문초등학교 | W37: 특수학급 | Y37: 0.97 | Z37: 토평초등학교 | AA37: 특수학급 | AC37: 1.1 | AD37: 010-7737-6854 | AP37: 주소 확인자 서명 누락. 수정요청. / 수정완료 | AQ37: 완료 | AR37: 완료
A38: 35 | B38: 일본사이타마시립특별지원학교 | D38: 1 | E38: 양세린 | F38: 여 | G38: 2019.12.30. | I38: O | J38: 지적장애 | M38: 경기도 남양주시 다산중앙로82번길 106, 6401동 2605호 | N38: 다산별빛초등학교 | O38: 특수학급 | Q38: 0.321 | R38: 다산별빛초등학교 | S38: 특수학급 | U38: 0.321 | V38: 다산새봄초등학교 | W38: 특수학급 | Y38: 0.7 | Z38: 금교초등학교 | AA38: 특수학급 | AC38: 0.833 | AD38: 010-8175-2518 | AF38: 구리남양주 | AG38: 경은학교 | AH38: 특수학교 | AO38: ※2026년 1월 22일 검사 실시 □ K-WPPSI-Ⅳ: 전체IQ 41(언어이해 50, 시공간 46, 유동추론 45, 작업기억 45, 처리속도 45/매우 낮음) □ 사회성숙도: SA 2세8개월, SQ 44.66(중등도) □ 적응행동: 표준점수 51(상당히 저조한 수준) | AP38: 특수학교를 희망하나 일본에 거주 중이라, 7~8월 중 심층관찰 일정 협의 예정 | AQ38: 완료 | AR38: 완료
A39: 36 | B39: 시립하나어린이집 | D39: 3 | E39: 윤하진 | F39: 남 | G39: 2018.02.11. | I39: O | J39: 중도중복장애 | K39: 지적·뇌병변장애 | L39: 중증 | M39: 경기도 남양주시 화도읍 비룡로 56-8, 101동 1802호 | N39: 남양주송라초등학교 | O39: 특수학급 | Q39: 0.629 | R39: 남양주송라초등학교 | S39: 특수학급 | U39: 0.629 | V39: 마석초등학교 | W39: 특수학급 | Y39: 1.3 | Z39: 은솔초등학교 | AA39: 특수학급 | AC39: 1.4 | AD39: 010-4310-8179 | AF39: 구리남양주 | AG39: 경은학교 | AH39: 특수학교 | AO39: □ 복지카드: 지적·뇌병변장애 중증(~2030.10.24.) □ 장애인증명서(지적장애 심한장애, 뇌병변 심한장애, 2019.07.05.) | AP39: 장애인증명서 확인 필요 / 제출완료 | AQ39: 완료 | AR39: 완료
A40: 37 | B40: 평내초등학교병설유치원 | C40: 순회학급 | D40: 3 | E40: 김보라 | F40: 여 | G40: 2020.08.28. | H40: O | J40: 지체장애 | K40: 뇌병변 | L40: 중증 | M40: 경기도 남양주시 화도읍 녹촌로20, 101동1103호(신한토탈아파트) | N40: 창현초등학교 | O40: 특수학급 | Q40: 0.31 | R40: 마석초등학교 | S40: 순회학급 | U40: 0.984 | V40: 평동초등학교 | W40: 순회학급 | Y40: 6.1 | Z40: 남양주동곡초등학교 | AA40: 순회학급 | AC40: 11 | AD40: 010-6547-0279 | AF40: 구리남양주 | AG40: 복합특수학급신설 | AO40: □ 장애인증명서: 뇌병변 심한 | AP40: 순회학급 | AQ40: 완료 | AR40: 완료
...

Sheet 특수학교 희망
A1: 연번 | B1: 소속교 | C1: 학급유형 | D1: 학년 | E1: 성명 | F1: 성별 | G1: 생년월일 | H1: 선정배치 | J1: 장애유형 | M1: 주소 | N1: 최근거리교 | Q1: 희망교 | Z1: 연락처 | AB1: 특수학교(유치부) | AK1: 검사결과 | AL1: 특이사항 | AM1: 심층관찰 | AO1: 2: 학교 자리만 있으면 들어가도 좋을듯
H2: 기존 | I2: 신규 | J2: 특수교육법 | K2: 장애인복지법 | N2: 학교명 | O2: 배치유형 | P2: 거리(km) | Q2: 1희망교 | T2: 2희망교 | W2: 3희망교 | AB2: 1희망 | AE2: 2희망 | AH2: 3희망 | AO2: 3: 애매...함. 약 먹으면, 적응하면 학급도 지낼만 할텐데
J3: 영역 | K3: 영역 | L3: 정도 | Q3: 학교명 | R3: 배치유형 | S3: 거리(km) | T3: 학교명 | U3: 배치유형 | V3: 거리(km) | W3: 학교명 | X3: 배치유형 | Y3: 거리(km) | Z3: 보호자 | AA3: 담당교사 | AB3: 지역 | AC3: 학교명 | AD3: 학급유형 | AE3: 지역 | AF3: 학교명 | AG3: 학급유형 | AH3: 지역 | AI3: 학교명 | AJ3: 학급유형 | AO3: 4: 학급이 오히려 나아 보이는
A4: 1 | B4: 구리시립갈매어린이집 | D4: 3 | E4: 이인규 | F4: 남 | G4: 2020.11.12. | I4: O | J4: 의사소통장애 | M4: 경기도 남양주시 퇴계원읍 도제원로 89-1, 102동 301호(삼성하이츠) | N4: 퇴계원초등학교 | O4: 특수학급 | P4: 0.783 | Q4: 퇴계원초등학교 | R4: 특수학급 | S4: 0.783 | T4: 도제원초등학교 | U4: 특수학급 | V4: 1.1 | W4: 내양초등학교 | X4: 특수학급 | Y4: 2.4 | Z4: 010-4397-1648 | AB4: 구리남양주 | AC4: 경은학교 | AD4: 특수학교 | AE4: 구리남양주 | AF4: 복합특수학급 신설 | AG4: 복합특수학급 | AK4: ※2026년 7월 9일 검사 실시 □K-WPPSI-IV: 전체IQ 40 (언어이해 45, 시공간 79, 유동추론 45, 작업기억 45, 처리속도 45/매우 낮음) □적응행동검사: 표준점수 54(상당히 저조한 수준) □사회성숙도: SA 1세 11개월, SQ 35.30(중등도) | AM4: 다음 수 오전, 2시 이후 / 29,30 오전.. 오전이 가장 일상적인 모습. 오후는 2시~3시 / 24일(수) 14시 샘 메일 unghea12@naver.com | AO4: 4 | AP4: 진단평가 필요, 약X, 인지 양호, 장애미등록
A5: 2 | B5: 시립토평마을어린이집 | D5: 3 | E5: 박규빈 | F5: 남 | G5: 2020.07.17. | I5: O | J5: 자폐성장애 | K5: 자폐성장애 | L5: 중증 | M5: 경기도 남양주시 다산중앙로146번길7, 2205동 1101호 | N5: 남양주다산초등학교 | O5: 특수학급 | P5: 0.48 | Q5: 남양주다산초등학교 | R5: 특수학급 | S5: 0.48 | T5: 다산하늘초등학교 | U5: 특수학급 | V5: 0.85 | W5: 다산새봄초등학교 | X5: 특수학급 | Y5: 1 | Z5: 010-7320-1455 | AB5: 구리남양주 | AC5: 경은학교 | AD5: 특수학교 | AE5: 구리남양주 | AF5: 복합특수학급 신설 | AK5: □ 복지카드: 자폐성장애 중증(~2032.06.19.) | AL5: 1,2희망교 도보 통학 기준 | AM5: 6/26(금), 6/29(월), 6/30(화) 10시 교사메일: sde1109@naver.com | AO5: 4 | AP5: 사회적 상황 인지, 따르기 모두 양호. 자기자극 중심의 활동일뿐 방해 크지 않았음
A6: 3 | B6: 다움어린이집 | D6: 3 | E6: 이예찬 | F6: 남 | G6: 2019.06.24. | I6: O | J6: 자폐성장애 | K6: 자폐성장애 | L6: 심한 | M6: 경기도 남양주시 화도읍 먹갓로 28번길 39-12 신강남 가-102호 | N6: 천마초등학교 | O6: 특수학급 | P6: 0.12 | Q6: 천마초등학교 | R6: 특수학급 | S6: 0.12 | T6: 은솔초등학교 | U6: 특수학급 | V6: 2.2 | W6: 남양주송라초등학교 | X6: 특수학급 | Y6: 2.4 | Z6: 010-3217-6485 | AB6: 구리남양주 | AC6: 경은학교 | AD6: 특수학교 | AE6: 의정부 | AF6: 송민학교 | AG6: 특수학교 | AH6: 구리남양주 | AI6: 복합특수학급신설 | AK6: □ 장애인증명서: 자폐성장애 심한 | AM6: 23일(화) 10시 수요일 학생 센터 일정으로 어려움. thewood@naver.com / 10시 / 원장님 | AO6: 3 | AP6: 1년 유예, 약 잠시 먹다 중단, 영아반에서 생활... 교육기회 부족으로 인한 현행수준으로 보임. 방방 뛰는거 말고는 크게 방해X
A7: 4 | B7: 남양주도담유치원 | C7: 특수학급 | D7: 3 | E7: 윤시우 | F7: 남 | G7: 2020.01.07. | H7: O | J7: 발달지체 | M7: 경기도 남양주시 진접읍 봉현로 36번길 11-1, 105동 506호(삼신아파트) | N7: 장현초등학교 | O7: 특수학급 | P7: 0.2 | Q7: 장현초등학교 | R7: 특수학급 | S7: 0.2 | T7: 화봉초등학교 | U7: 특수학급 | V7: 2.2 | W7: 장승초등학교 | X7: 특수학급 | Y7: 2.5 | Z7: 010-4903-3602 | AA7: 손효주 | AB7: 구리남양주 | AC7: 경은학교 | AD7: 특수학교 | AE7: 구리남양주 | AF7: 복합특수학급신설 | AK7: 기존 | AM7: 25일(목) 10시 / 3층 은하반 | AO7: 3 | AP7: 장애미등록, 약X
A8: 5 | B8: 창현유치원 | C8: 특수학급 | D8: 3 | E8: 최은우 | F8: 남 | G8: 2020.01.14. | H8: O | J8: 발달지체 | M8: 경기도 남양주시 화도읍 창현로 45, 104동 601호(신창현도뮤토아파트) | N8: 마석초등학교 | O8: 특수학급 | P8: 0.76 | Q8: 마석초등학교 | R8: 특수학급 | S8: 0.76 | T8: 창현초등학교 | U8: 특수학급 | V8: 0.32 | W8: 은솔초등학교 | X8: 특수학급 | Y8: 1.3 | Z8: 010-5555-9213 | AA8: 허원영 | AB8: 구리남양주 | AC8: 경은학교 | AD8: 특수학교 | AE8: 구리남양주 | AF8: 복합특수학급신설 | AH8: 광주하남 | AI8: 성광학교 | AJ8: 특수학교 | AL8: 장애유형, 특수학교 희망교 수정 요청 / 최근거리는 창현초이지만, 학구가 마석초등학교임 | AM8: 7/1(수)10, 7/2(목)10:40, 7/8)수)10, 7/9(목)10:40 | AO8: 3 | AP8: 장애미등록, 약X, 현재 모습은 과잉행동, 충동성 문제가 심각하지만, 교육을 위해 장애등록 및 의료적 접근 필요해보임... 등록이라도 됐으면 더 고려해봄직 했을텐데..
A9: 6 | B9: 시립행복모아어린이집 | D9: 3 | E9: 김하린 | F9: 여 | G9: 2020.09.02. | I9: O | J9: 중도중복장애 | K9: 뇌병변장애 | L9: 중증 | M9: 경기도 남양주시 와부읍 덕소로 270, 113동 405호 | N9: 도심초등학교 | O9: 특수학급 | P9: 1.4 | Q9: 도심초등학교 | R9: 특수학급 | S9: 1.4 | T9: 남양주도곡초등학교 | U9: 특수학급 | V9: 0.994 | W9: 덕소초등학교 | X9: 특수학급 | Y9: 2 | Z9: 010-4410-6462 | AB9: 구리남양주 | AC9: 경은학교 | AD9: 특수학교 | AE9: 구리남양주 | AF9: 복합특수학급 신설 | AG9: 복합특수학급 | AK9: □ 복지카드: 뇌병변장애 중증(~2029.02.14.) □ 장애인증명서(지적장애 심한 장애, 뇌병변 심한 장애, 2026.06.12.) | AM9: 학부모, 담임 소통 후 회신 예정(16,17일경) 24(수)10시반, 26(금)10시반, 7/1(수)10시반 10시로 수정 교사메일: joy1726@naver.com | AO9: 1a | AP9: 중도중복. 걷기 시작한 돌 아기 느낌.
A10: 7 | B10: 경은학교 | C10: 특수학교 | D10: 3 | E10: 김하람 | F10: 남 | G10: 2020.03.15. | H10: O | J10: 자폐성장애 | K10: 자폐성장애 | L10: 중증 | M10: 경기도 남양주시 별내면 68번길 24, 402동 2001호 | N10: 별내초등학교 | O10: 특수학급 | P10: 0.711 | Q10: 별내초등학교 | R10: 특수학급 | S10: 0.711 | T10: 샛별초등학교 | U10: 특수학급 | V10: 5.5 | W10: 남양주덕송초등학교 | X10: 특수학급 | Y10: 6.2 | Z10: 010-4860-5847 | AA10: 손신애 | AB10: 구리남양주 | AC10: 경은학교 | AD10: 특수학교 | AK10: □ 복지카드: 자폐성장애 중증(~2031.10.03.) | AL10: 자폐로 장애유형 변경 요청 / 배치희망교 2,3순위 고산에서 샛별, 덕송으로 변경 요청 | AM10: 19(금) 08:50 | AO10: 1b | AP10: 인지 너무 낮고, 자폐 성향 매우 강함.
A11: 8 | B11: 하늘숲어린이집 | D11: 3 | E11: 양서율 | F11: 여 | G11: 2020.01.26. | I11: O | J11: 자폐성장애 | K11: 자폐성장애 | L11: 중증 | M11: 경기도 남양주시 오남읍 양지로46번길 130, 102동 503호 | N11: 오남초등학교 | O11: 특수학급 | P11: 0.633 | Q11: 오남초등학교 | R11: 특수학급 | S11: 0.633 | T11: 남양주양지초등학교 | U11: 특수학급 | V11: 1.2 | W11: 양오초등학교 | X11: 특수학급 | Y11: 1.8 | Z11: 010-2228-7151 | AB11: 구리남양주 | AC11: 경은학교 | AD11: 특수학교 | AE11: 구리남양주 | AF11: 복합특수학급 신설 | AG11: 복합특수학급 | AH11: 의정부 | AI11: 송민학교 | AJ11: 특수학교 | AK11: □ 복지카드: 자폐성장애 중증(~2028.09.28.) | AM11: 7/2((목) 10시 7/8(수)2시 010-8727-4730 김지희선생님 merowith2@naver.com | AO11: 2b | AP11: 구지초병유 김시율보다 조금 약한 정도. 교육이 덜 되었지만, 자폐 여아 치고는 행동문제가 비교적 적음. 인지, 소근육 높진 않음. 자폐 성향은 강해보임. 활동도 매우 제한적임. 통합 어려움 예상은 됨.
A12: 9 | B12: 시립미사어린이집 | D12: 3 | E12: 한준영 | F12: 남 | G12: 2020.04.07. | I12: O | J12: 지적장애 | K12: 지적·뇌병변장애 | L12: 중증 | M12: 경기도 남양주시 천마산로12번길 19-10, 101동 404호(메종드힐) | N12: 호평초등학교 | O12: 특수학급 | P12: 0.935 | Q12: 호평초등학교 | R12: 특수학급 | S12: 0.935 | T12: 평동초등학교 | U12: 특수학급 | V12: 1.3 | W12: 구룡초등학교 | X12: 특수학급 | Y12: 1.4 | Z12: 010-5219-0736 | AB12: 구리남양주 | AC12: 경은학교 | AD12: 특수학교 | AE12: 의정부 | AF12: 송민학교 | AG12: 특수학교 | AK12: □ 복지카드: 지적·뇌병변장애 중증(~2027.11.09.) | AL12: 특수학교 입학 불가 시 유예 희망 | AM12: 2명 장애전담 / 24일 10~11시 slms2018@hanmail.net
A13: 10 | B13: 시립미사어린이집 | D13: 3 | E13: 박교빈 | F13: 남 | G13: 2020.10.19. | I13: O | J13: 지적장애 | K13: 지적·뇌병변장애 | L13: 심한 | M13: 경기도 구리시 장자대로37번길 55, 106동 1101호 | N13: 백문초등학교 | O13: 특수학급 | P13: 0.578 | Q13: 백문초등학교 | R13: 특수학급 | S13: 0.578 | T13: 도림초등학교 | U13: 특수학급 | V13: 0.741 | W13: 교문초등학교 | X13: 특수학급 | Y13: 1 | Z13: 010-7640-7460 | AB13: 구리남양주 | AC13: 경은학교 | AD13: 특수학교 | AE13: 구리남양주 | AF13: 복합특수학급 신설 | AG13: 복합특수학급 | AH13: 의정부 | AI13: 송민학교 | AJ13: 특수학교 | AK13: □ 장애인증명서: 지적·뇌병변장애 심한 (발급일: 2026.06.15.) | AL13: 복지카드 유효기한은 2027년 2월이나 장애인증명서가 있어서 갈음 가능함 | AM13: 2명 장애전담 / 24일 10~11시 slms2018@hanmail.net
A14: 11 | B14: 영진햇살어린이집 | D14: 3 | E14: 최민재 | F14: 남 | G14: 2020.01.10. | I14: O | J14: 자폐성장애 | K14: 자폐성장애 | L14: 심한 | M14: 경기도 남양주시 화도읍 경춘로 1922번길 16, 202호 | N14: 마석초등학교 | O14: 특수학급 | P14: 0.311 | Q14: 마석초등학교 | R14: 특수학급 | S14: 0.311 | T14: 창현초등학교 | U14: 특수학급 | V14: 0.768 | W14: 남양주송라초등학교 | X14: 특수학급 | Y14: 0.858 | Z14: 010-3361-0124 | AB14: 구리남양주 | AC14: 경은학교 | AD14: 특수학교 | AK14: □ 복지카드: 자폐성장애 중증(~2032.1.17.) | AL14: 특수학교 기각되면 취학유예 예정 | AM14: 매주 수요일 결석 26일 14~16시 연락 jjin4846@naver.com
A15: 12 | B15: 시립하나어린이집 | D15: 3 | E15: 윤하진 월 | F15: 남 | G15: 2018.02.11. | I15: O | J15: 중도중복장애 | K15: 지적·뇌병변장애 | L15: 중증 | M15: 경기도 남양주시 화도읍 비룡로 56-8, 101동 1802호 | N15: 남양주송라초등학교 | O15: 특수학급 | P15: 0.629 | Q15: 남양주송라초등학교 | R15: 특수학급 | S15: 0.629 | T15: 마석초등학교 | U15: 특수학급 | V15: 1.3 | W15: 은솔초등학교 | X15: 특수학급 | Y15: 1.4 | Z15: 010-4310-8179 | AB15: 구리남양주 | AC15: 경은학교 | AD15: 특수학교 | AK15: □ 복지카드: 지적·뇌병변장애 중증(~2030.10.24.) | AL15: 장애인증명서 제출 완료 | AM15: 27(월) 10~11시 nyjhana@naver.com
A16: 13 | B16: 시립하나어린이집 | D16: 3 | E16: 유태영 월 | F16: 남 | G16: 2019.11.18. | I16: O | J16: 지적장애 | K16: 지적장애 | L16: 심한 | M16: 경기도 남양주시 화도읍 경춘로 2290번길2, 105동102호 | N16: 남양주월산초등학교 | O16: 특수학급 | P16: 0.375 | Q16: 남양주월산초등학교 | R16: 특수학급 | S16: 0.375 | T16: 마석초등학교 | U16: 특수학급 | V16: 3.9 | W16: 남양주송라초등학교 | X16: 특수학급 | Y16: 4.5 | Z16: 010-7105-1116 | AB16: 구리남양주 | AC16: 경은학교 | AD16: 특수학교 | AK16: □ 장애인증명서: 지적장애 심한장애 | AL16: 특수학교 기각되면 취학유예 예정 | AM16: 27(월) 10~11시
A17: 14 | B17: 시립하나어린이집 | D17: 3 | E17: 박시영 월 | F17: 여 | G17: 2018.09.17. | I17: O | J17: 지체장애 | K17: 뇌병변장애 | L17: 중증 | M17: 경기도 남양주시 화도읍 비룡로 56-8, 105동301호 | N17: 남양주송라초등학교 | O17: 특수학급 | P17: 0.3 | Q17: 남양주송라초등학교 | R17: 특수학급 | S17: 0.3 | T17: 마석초등학교 | U17: 특수학급 | V17: 1.3 | W17: 화도초등학교 | X17: 특수학급 | Y17: 1.4 | Z17: 010-8610-4533 | AB17: 구리남양주 | AC17: 경은학교 | AD17: 특수학교 | AK17: □ 장애인증명서: 뇌병변 심한장애 | AL17: 경은 기각되면 취학유예 또는 재활 위해 면제 고려중 | AM17: 27(월) 10~11시 / 학급 다름
A18: 15 | B18: 시립하나어린이집 | D18: 3 | E18: 이윤아 수 | F18: 여 | G18: 2019.03.12. | I18: O | J18: 자폐성장애 | K18: 자폐성장애 | L18: 중증 | M18: 경기도 남양주시 백봉로 32, 105동 701동 | N18: 하랑초등학교 | O18: 특수학급 | P18: 0.639 | Q18: 평동초등학교 | R18: 특수학급 | S18: 0.984 | T18: 구룡초등학교 | U18: 특수학급 | V18: 1 | W18: 평내초등학교 | X18: 특수학급 | Y18: 1.9 | Z18: 010-5910-4061 | AB18: 구리남양주 | AC18: 경은학교 | AD18: 특수학교 | AE18: 구리남양주 | AF18: 복합특수학급 신설 | AG18: 복합특수학급 | AK18: □ 복지카드: 자폐성장애 중증(~2030.10.22.) | AL18: 내년에 초등학교 입학하는 비장애 자녀와 다른 학교 배치를 희망하요 1~3희망교를 모두 학구 외로 기재 | AM18: 29(수) 10~11시
A19: 16 | B19: 시립하나어린이집 | D19: 3 | E19: 김주하 수 | F19: 남 | G19: 2019.03.03. | I19: O | J19: 자폐성장애 | K19: 자폐성장애 | L19: 중증 | M19: 경기도 남양주시 화도읍 경춘로 2290번길2, 111동103호 | N19: 남양주월산초등학교 | O19: 특수학급 | P19: 0.187 | Q19: 남양주월산초등학교 | R19: 특수학급 | S19: 0.187 | T19: 마석초등학교 | U19: 특수학급 | V19: 3.8 | W19: 남양주송라초등학교 | X19: 특수학급 | Y19: 4.4 | Z19: 010-3222-5480 | AB19: 구리남양주 | AC19: 경은학교 | AD19: 특수학교 | AE19: 구리남양주 | AF19: 복합특수학급신설 | AK19: □ 복지카드: 자폐성장애 중증(~2039.01.11.) | AL19: 가족관계증명서, 등본 제출(한부모) | AM19: 29(수) 10~11시
A20: 17 | B20: 노원구 초록어린이집 | D20: 3 | E20: 이희민 | F20: 남 | G20: 2020.03.23. | I20: O | J20: 자폐성장애 | K20: 자폐성장애 | L20: 중증 | M20: 경기도 남양주시 별내3로 159, 2707동 704호 | N20: 별가람초등학교 | O20: 특수학급 | P20: 0.01 | Q20: 별가람초등학교 | R20: 특수학급 | S20: 0.01 | T20: 화접초등학교 | U20: 특수학급 | V20: 1.1 | W20: 한별초등학교 | X20: 특수학급 | Y20: 2 | Z20: 010-3738-8719 | AA20: 김찬희(어린이집) | AB20: 구리남양주 | AC20: 경은학교 | AD20: 특수학교 | AE20: 구리남양주 | AF20: 복합특수학급 신설 | AG20: 복합특수학급 | AH20: 의정부 | AI20: 송민학교 | AJ20: 특수학교 | AK20: □ 복지카드: 자폐성장애 중증(~2032.03.31.) | AM20: platanus4@hanmail.net 7/16(목) 10시 | AO20: 4
A21: 18 | B21: 일본사이타마시립특별지원학교 | C21: 일본 | D21: 1 | E21: 양세린 | F21: 여 | G21: 2019.12.30. | I21: O | J21: 지적장애 | M21: 경기도 남양주시 다산중앙로82번길 106, 6401동 2605호 | N21: 다산별빛초등학교 | O21: 특수학급 | P21: 0.321 | Q21: 다산별빛초등학교 | R21: 특수학급 | S21: 0.321 | T21: 다산새봄초등학교 | U21: 특수학급 | V21: 0.7 | W21: 금교초등학교 | X21: 특수학급 | Y21: 0.833 | Z21: 010-8175-2518 | AB21: 구리남양주 | AC21: 경은학교 | AD21: 특수학교 | AK21: ※2026년 1월 22일 검사 실시 □ K-WPPSI-Ⅳ: 전체IQ 41(언어이해 50, 시공간 46, 유동추론 45, 작업기억 45, 처리속도 45/매우 낮음) □ 사회성숙도: SA 2세8개월, SQ 44.66(중등도) □ 적응행동: 표준점수 51(상당히 저조한 수준) | AL21: 특수학교를 희망하나 일본에 거주 중이라, 7~8월 중 심층관찰 일정 협의 예정 / 현재 귀국 예정은 없고, 8/21(금)까지 심층 마쳐야 함을 문자로 안내함. | AM21: 일본 거주 / 7~8월쯤 협의
A22: 19 | B22: 구지초등학교병설유치원 | C22: 특수학급 | D22: 3 | E22: 김시율 | F22: 여 | G22: 2020.08.12. | H22: O | J22: 자폐성장애 | K22: 자폐성장애 | L22: 중증 | M22: 경기도 구리시 경춘로 276번길 21, 105동202호 | N22: 구리초등학교 | O22: 특수학급 | P22: 0.146 | Q22: 구리초등학교 | R22: 특수학급 | S22: 0.146 | T22: 구지초등학교 | U22: 특수학급 | V22: 1.2 | W22: 동구초등학교 | X22: 특수학급 | Y22: 1.4 | Z22: 010-5116-2446 | AA22: 한미선 | AB22: 구리남양주 | AC22: 경은학교 | AD22: 특수학교 | AK22: □ 복지카드: 자폐성장애 중증(~2031.12.30.) | AM22: 7/1,7/10 제외만. 7/9(목) 10시 | AN22: 유치원 | AO22: 2a | AP22: 약 안먹긴 하지만, 임팩트 가장 큼, 안정기에도 복도 생활.. 전형적 자폐 여아
A23: 20 | B23: 다산한강유치원 | C23: 특수학급 | D23: 3 | E23: 김태리 | F23: 남 | G23: 2020.01.20. | H23: O | J23: 자폐성장애 | K23: 자폐성,언어장애 | L23: 중증 | M23: 경기도 남양주시 다산지금로 146번길 117, 7511-1901 | N23: 다산한강초등학교 | O23: 특수학급 | P23: 0.23 | Q23: 다산한강초등학교 | R23: 특수학급 | S23: 0.23 | T23: 가운초등학교 | U23: 특수학급 | V23: 1.8 | W23: 양정초등학교 | X23: 특수학급 | Y23: 2.3 | Z23: 010-8504-2941 | AA23: 김해지 | AB23: 구리남양주 | AC23: 경은학교 | AD23: 특수학교 | AE23: 광주하남 | AF23: 성광학교 | AG23: 특수학교 | AH23: 구리남양주 | AI23: 사능초등학교 | AJ23: 복합특수학급 | AK23: □ 복지카드: 자폐성,언어장애 중증(~2031.10.14.) | AL23: 하남 성광학교를 2희망으로. / 경은을 1희망으로 수정 | AM23: 2명 같은 반 / 7/15(수) 10시 | AN23: 유치원 | AO23: 3
A24: 21 | B24: 다산한강유치원 | C24: 특수학급 | D24: 3 | E24: 이해빈 | F24: 여 | G24: 2020.05.13. | H24: O | J24: 자폐성장애 | K24: 자폐성장애 | L24: 중증 | M24: 경기도 남양주시 다산지금로 146번길 117, 7502동 2902호 | N24: 다산한강초등학교 | O24: 특수학급 | P24: 0.036 | Q24: 다산한강초등학교 | R24: 특수학급 | S24: 0.036 | T24: 남양주양정초등학교 | U24: 특수학급 | W24: 도농초등학교 | X24: 특수학급 | Z24: 010-5377-5204 | AA24: 김해지 | AB24: 구리남양주 | AC24: 경은학교 | AD24: 특수학교 | AK24: □ 복지카드: 자폐성장애 중증(~2032.02.03.) | AL24: 근거리 가운초, 양정초 순 안내 / 의견서 추가 예정 | AM24: 2명 같은 반 / 7/15(수) 10시 | AN24: 유치원 | AO24: 4
A25: 22 | B25: 산마루초등학교병설유치원 | C25: 특수학급 | D25: 3 | E25: 김서율 | F25: 여 | G25: 2020.10.03. | H25: O | J25: 발달지체 | M25: 경기도 구리시 갈매순환로 204번길 8-32, 202호(갈매동) | N25: 산마루초등학교 | O25: 특수학급 | Q25: 산마루초등학교 | R25: 특수학급 | T25: 갈매초등학교 | U25: 특수학급 | W25: 내양초등학교 | X25: 특수학급 | Z25: 010-9769-4972 | AA25: 안선영 | AB25: 구리남양주 | AC25: 경은학교 | AD25: 특수학교 | AM25: 8,14,15,16,22 제외 가능 / 21일(화) 10시 | AN25: 유치원
A26: 23 | B26: 산마루초등학교병설유치원 | C26: 특수학급 | D26: 3 | E26: 정지현 | F26: 여 | G26: 2020.09.15. | H26: O | J26: 자폐성장애 | K26: 자폐성장애 | L26: 중증 | M26: 경기도 구리시 갈매중앙로 131, 303동 1103호(갈매동, 한라비발디) | N26: 산마루초등학교 | O26: 특수학급 | Q26: 산마루초등학교 | R26: 특수학급 | T26: 갈매초등학교 | U26: 특수학급 | W26: 한별초등학교 | X26: 특수학급 | Z26: 010-4345-0582 | AA26: 안선영 | AB26: 구리남양주 | AC26: 경은학교 | AD26: 특수학교 | AM26: 8,14,15,16,22 제외 가능 / 21일(화) 10시 | AN26: 유치원
A27: 24 | B27: 화도은솔유치원 | C27: 특수학급 | D27: 3 | E27: 진시아 | F27: 여 | G27: 2020.03.19. | H27: O | J27: 발달지체 | K27: 자폐성장애 | L27: 중증 | M27: 경기도 남양주시 화도읍 비룡로 56-8, 107동 303호 (신명스카이뷰그린) | N27: 남양주송라초 | O27: 특수학급 | Q27: 남양주송라초등학교 | R27: 특수학급 | T27: 마석초 | U27: 특수학급 | W27: 화도초 | X27: 특수학급 | Z27: 010-9153-1455 | AA27: 류창준 | AB27: 구리남양주 | AC27: 경은학교 | AD27: 특수학교 | AM27: 2명 다른 반 / 7/10(금) 10시~12시 | AN27: 유치원 | AO27: 4
A28: 25 | B28: 부평초등학교병설유치원 | C28: 특수학급 | D28: 3 | E28: 오세준 | F28: 남 | G28: 2020.02.10. | H28: O | J28: 자폐성장애(발달지체) | K28: 자폐성장애 | L28: 중증 | M28: 경기도 남양주시 진접읍 부평로 48번길 110, 104동1801호 (진접서희스타힐스) | N28: 부평초등학교 | O28: 특수학급 | P28: 0.552 | Q28: 부평초등학교 | R28: 특수학급 | S28: 0.552 | T28: 진접초등학교 | U28: 특수학급 | V28: 3.1 | W28: 장승초등학교 | X28: 특수학급 | Y28: 1.5 | Z28: 010-5481-4321 | AA28: 김영미 | AB28: 구리남양주 | AC28: 경은학교 | AD28: 특수학교 | AE28: 구리남양주 | AF28: 복합특수학급 신설 | AG28: 특수학급 | AK28: □ 복지카드: 자폐성장애 중증(~2031.7.1.) | AL28: *2근거리 장승초, 3근거리 광릉초 안내 | AM28: 22일(수) 10시 | AN28: 유치원
A31: 광주하남 7.20부터 발송
A32: 의정부 9월 특운위 마치고 발송

Sheet 심층관찰(6-7월)
A1: 46174
A2: 일 | B2: 월 | C2: 화 | D2: 수 | E2: 목 | F2: 금 | G2: 토
B3: 1 | C3: 2 | D3: 3 | E3: 4 | F3: 5 | G3: 6
A4: 7 | B4: 8 | C4: 9 | D4: 10 | E4: 11 | F4: 12 | G4: 13
A5: 14 | B5: 15 | C5: 16 | D5: 17 | E5: 18 | F5: 19 경은 9시 김하람 | G5: 20
A6: 21 | B6: 22 | C6: 23 다움어린이집 10시 이예찬 | D6: 24 시립갈매어린이집 14시 이인규 | E6: 25 남양주도담유치원 10시 윤시우 | F6: 26 | G6: 27
A7: 28 | B7: 29 | C7: 30 시립토평마을어린이집 10시 박규빈
A9: 46204
A10: 일 | B10: 월 | C10: 화 | D10: 수 | E10: 목 | F10: 금 | G10: 토
D11: 1 시립행복모아어린이집(광주하남) 10시30분 김하린 | E11: 2 창현유치원 10시40분 최은우 | F11: 3 | G11: 4
A12: 5 | B12: 6 | C12: 7 | D12: 8 | E12: 9 | F12: 10 | G12: 11
A13: 12 | B13: 13 | C13: 14 | D13: 15 | E13: 16 | F13: 17 | G13: 18
A14: 19 | B14: 20 | C14: 21 | D14: 22 | E14: 23 | F14: 24 | G14: 25
A15: 26 | B15: 27 | C15: 28 | D15: 29 | E15: 30 | F15: 31

Sheet 27.3.1.자 재배치
A1: 연번 | B1: 소속교 | C1: 학급유형 | D1: 학년 | E1: 성명 | F1: 성별 | G1: 생년월일 | H1: 장애유형 | K1: 주소 | L1: 최근거리교 | O1: 희망교 | X1: 연락처 | Z1: 특수학교 | AI1: 특이사항 | AJ1: 접수완료
H2: 특수교육법 | I2: 장애인복지법 | L2: 학교명 | M2: 배치유형 | N2: 거리(km) | O2: 1희망교 | R2: 2희망교 | U2: 3희망교 | Z2: 1희망 | AC2: 2희망 | AF2: 3희망
H3: 영역 | I3: 영역 | J3: 정도 | O3: 학교명 | P3: 배치유형 | Q3: 거리(km) | R3: 학교명 | S3: 배치유형 | T3: 거리(km) | U3: 학교명 | V3: 배치유형 | W3: 거리(km) | X3: 보호자 | Y3: 담당교사 | Z3: 지역 | AA3: 학교명 | AB3: 학급유형 | AC3: 지역 | AD3: 학교명 | AE3: 학급유형 | AF3: 지역 | AG3: 학교명 | AH3: 학급유형
A4: 1 | B4: 갈매초등학교 | C4: 특수학급 | D4: 1 | E4: 장우준 | F4: 남 | G4: 2018.04.18. | H4: 지적장애 | I4: 지적장애 | J4: 중증 | K4: 경기도 구리시 갈매중앙로 131, 311-102 | L4: 산마루초등학교 | M4: 특수학급 | N4: 1.1 | O4: 산마루초등학교 | P4: 특수학급 | Q4: 0.845 | R4: 내양초등학교 | S4: 특수학급 | T4: 2.2 | X4: 010-4772-0929 | Y4: 강혜은 | AI4: 산마루초 학구인데, 갈매초에 배치되었었음. / 도보임 | AJ4: 완료

Sheet 초입 (특수학급)
A1: 연번 | B1: 구분 | C1: 선정배치 | E1: 소속교 | F1: 학급유형 | G1: 학년 | H1: 성명 | I1: 성별 | J1: 생년월일 | K1: 장애유형(유형변경 고려 필요) | N1: 최근거리교 | R1: 희망교 | V1: 검사결과 | W1: 특이사항 | X1: 연락처 | Z1: 주소
C2: 기존 | D2: 신규 | K2: 특수교육법 | L2: 장애인복지법 | N2: 학교명 | O2: 배치유형 | P2: 통학방법 | Q2: 거리(km) | R2: 학교명 | S2: 배치유형 | T2: 통학방법 | U2: 거리(km)
K3: 영역 | L3: 영역 | M3: 정도 | X3: 보호자 | Y3: 담당교사
A4: =초입!A4 -> 1 | B4: 초입 | C4: =IF(초입!H4<>"","O","") | D4: =IF(초입!I4<>"","O","") -> O | E4: =초입!B4 -> 시립동구어린이집 | F4: =IF(초입!C4="","",초입!C4) | G4: =IF(초입!D4="","",초입!D4) -> 3 | H4: =IF(초입!E4="","",초입!E4) -> 김연성 | I4: =IF(초입!F4="","",초입!F4) -> 남 | J4: =IF(초입!G4="","",초입!G4) -> 2020.02.25. | K4: =IF(초입!J4="","",초입!J4) -> 의사소통장애 (지적장애 범주) | L4: =IF(초입!K4="","",초입!K4) | M4: =IF(초입!L4="","",초입!L4) | N4: =IF(초입!N4="","",초입!N4) -> 구리초등학교 | O4: =IF(초입!O4="","",초입!O4) -> 특수학급 | P4: =IF(초입!P4="","",초입!P4) | Q4: =IF(초입!Q4="","",초입!Q4) -> 0.1 | R4: =IF(초입!R4="","","1. "&초입!R4&IF(초입!V4<>"",CHAR(10)&"2. "&초입!V4,"")&IF(초입!Z4<>"",CHAR(10)&"3. "&초입!Z4,"")) -> 1. 구리초등학교 2. 구지초등학교 3. 동구초등학교 | S4: =IF(초입!S4="","",""&초입!S4&IF(초입!W4<>"",CHAR(10)&""&초입!W4,"")&IF(초입!AA4<>"",CHAR(10)&""&초입!AA4,"")) -> 특수학급 특수학급 특수학급 | T4: =IF(초입!T4="","",""&초입!T4&IF(초입!X4<>"",CHAR(10)&""&초입!X4,"")&IF(초입!AB4<>"",CHAR(10)&""&초입!AB4,"")) | U4: =IF(초입!U4="","",""&초입!U4&IF(초입!Y4<>"",CHAR(10)&""&초입!Y4,"")&IF(초입!AC4<>"",CHAR(10)&""&초입!AC4,"")) -> 0.1 1.2 1.4 | V4: =IF(초입!AO4="","",초입!AO4) -> ※심리평가보고서(2026.3.12.) □ K-WPPSI-Ⅳ: 전체IQ 53(언어이해 50, 시공간 79, 유동추론 66, 작업기억 61, 처리속도 64/매우 낮음) □ 사회성숙도: SA 4세7개월, SQ 78.33(경계선) □ CARS: 22.5점 □ 적응행동검사: 표준점수 70(저조한 수준) | W4: =IF(초입!AP4="","",초입!AP4) -> *검사결과 지적장애 범주. 신규지만 지적장애로 유형변경 | X4: =IF(초입!AD4="","",초입!AD4) -> 010-8865-6065 | Y4: =IF(초입!AE4="","",초입!AE4) | Z4: =IF(초입!M4="","",초입!M4) -> 경기도 구리시 경춘로276번길 21, 107동 1002호(구리역한양수자인)
A5: =초입!A5 -> 2 | B5: 초입 | C5: =IF(초입!H5<>"","O","") | D5: =IF(초입!I5<>"","O","") -> O | E5: =초입!B5 -> 없음 | F5: =IF(초입!C5="","",초입!C5) | G5: =IF(초입!D5="","",초입!D5) | H5: =IF(초입!E5="","",초입!E5) -> 김주연 | I5: =IF(초입!F5="","",초입!F5) -> 여 | J5: =IF(초입!G5="","",초입!G5) -> 2020.10.10. | K5: =IF(초입!J5="","",초입!J5) -> 지적장애 | L5: =IF(초입!K5="","",초입!K5) -> 지적·자폐성장애 | M5: =IF(초입!L5="","",초입!L5) -> 중증 | N5: =IF(초입!N5="","",초입!N5) -> 부양초등학교 | O5: =IF(초입!O5="","",초입!O5) -> 특수학급 | P5: =IF(초입!P5="","",초입!P5) | Q5: =IF(초입!Q5="","",초입!Q5) -> 0.454 | R5: =IF(초입!R5="","","1. "&초입!R5&IF(초입!V5<>"",CHAR(10)&"2. "&초입!V5,"")&IF(초입!Z5<>"",CHAR(10)&"3. "&초입!Z5,"")) -> 1. 부양초등학교 2. 백문초등학교 3. 토평초등학교 | S5: =IF(초입!S5="","",""&초입!S5&IF(초입!W5<>"",CHAR(10)&""&초입!W5,"")&IF(초입!AA5<>"",CHAR(10)&""&초입!AA5,"")) -> 특수학급 특수학급 특수학급 | T5: =IF(초입!T5="","",""&초입!T5&IF(초입!X5<>"",CHAR(10)&""&초입!X5,"")&IF(초입!AB5<>"",CHAR(10)&""&초입!AB5,"")) | U5: =IF(초입!U5="","",""&초입!U5&IF(초입!Y5<>"",CHAR(10)&""&초입!Y5,"")&IF(초입!AC5<>"",CHAR(10)&""&초입!AC5,"")) -> 0.454 1.2 1.2 | V5: =IF(초입!AO5="","",초입!AO5) -> □ 복지카드: 지적,자폐성장애 중증(~2032.03.02.) | W5: =IF(초입!AP5="","",초입!AP5) -> 7월30일 거주지 이전 / 대중교통 이용 / 현 주소 기준으로 거리 작성됨 / 자차기준 토평, 백문, 도림, 교문 모두 1.1~1.2km임 / 1순위 안되면 참고 | X5: =IF(초입!AD5="","",초입!AD5) -> 010-8999-2232 | Y5: =IF(초입!AE5="","",초입!AE5) | Z5: =IF(초입!M5="","",초입!M5) -> 현: 경기도 구리시 건원대로 92, 115동 1405호(인창동 주공아파트) 이사: 경기도 구리시 수택동 444-6
A6: =초입!A6 -> 3 | B6: 초입 | C6: =IF(초입!H6<>"","O","") | D6: =IF(초입!I6<>"","O","") -> O | E6: =초입!B6 -> 하늘숲어린이집 | F6: =IF(초입!C6="","",초입!C6) | G6: =IF(초입!D6="","",초입!D6) -> 3 | H6: =IF(초입!E6="","",초입!E6) -> 양서율 | I6: =IF(초입!F6="","",초입!F6) -> 여 | J6: =IF(초입!G6="","",초입!G6) -> 2020.01.26. | K6: =IF(초입!J6="","",초입!J6) -> 자폐성장애 | L6: =IF(초입!K6="","",초입!K6) -> 자폐성장애 | M6: =IF(초입!L6="","",초입!L6) -> 중증 | N6: =IF(초입!N6="","",초입!N6) -> 오남초등학교 | O6: =IF(초입!O6="","",초입!O6) -> 특수학급 | P6: =IF(초입!P6="","",초입!P6) | Q6: =IF(초입!Q6="","",초입!Q6) -> 1.4 | R6: =IF(초입!R6="","","1. "&초입!R6&IF(초입!V6<>"",CHAR(10)&"2. "&초입!V6,"")&IF(초입!Z6<>"",CHAR(10)&"3. "&초입!Z6,"")) -> 1. 오남초등학교 2. 남양주양지초등학교 3. 양오초등학교 | S6: =IF(초입!S6="","",""&초입!S6&IF(초입!W6<>"",CHAR(10)&""&초입!W6,"")&IF(초입!AA6<>"",CHAR(10)&""&초입!AA6,"")) -> 특수학급 특수학급 특수학급 | T6: =IF(초입!T6="","",""&초입!T6&IF(초입!X6<>"",CHAR(10)&""&초입!X6,"")&IF(초입!AB6<>"",CHAR(10)&""&초입!AB6,"")) | U6: =IF(초입!U6="","",""&초입!U6&IF(초입!Y6<>"",CHAR(10)&""&초입!Y6,"")&IF(초입!AC6<>"",CHAR(10)&""&초입!AC6,"")) -> 1.4 1.2 1.8 | V6: =IF(초입!AO6="","",초입!AO6) -> □ 복지카드: 자폐성장애 중증(~2028.09.28.) | W6: =IF(초입!AP6="","",초입!AP6) | X6: =IF(초입!AD6="","",초입!AD6) -> 010-2228-7151 | Y6: =IF(초입!AE6="","",초입!AE6) | Z6: =IF(초입!M6="","",초입!M6) -> 경기도 남양주시 오남읍 양지로46번길 130, 102동 503호
A7: =초입!A7 -> 4 | B7: 초입 | C7: =IF(초입!H7<>"","O","") | D7: =IF(초입!I7<>"","O","") -> O | E7: =초입!B7 -> 시립토평마을어린이집 | F7: =IF(초입!C7="","",초입!C7) | G7: =IF(초입!D7="","",초입!D7) -> 3 | H7: =IF(초입!E7="","",초입!E7) -> 신주원 | I7: =IF(초입!F7="","",초입!F7) -> 남 | J7: =IF(초입!G7="","",초입!G7) -> 2020.08.16. | K7: =IF(초입!J7="","",초입!J7) -> 자폐성장애 | L7: =IF(초입!K7="","",초입!K7) -> 자폐성장애 | M7: =IF(초입!L7="","",초입!L7) -> 중증 | N7: =IF(초입!N7="","",초입!N7) -> 부양초등학교 | O7: =IF(초입!O7="","",초입!O7) -> 특수학급 | P7: =IF(초입!P7="","",초입!P7) | Q7: =IF(초입!Q7="","",초입!Q7) -> 0.45 | R7: =IF(초입!R7="","","1. "&초입!R7&IF(초입!V7<>"",CHAR(10)&"2. "&초입!V7,"")&IF(초입!Z7<>"",CHAR(10)&"3. "&초입!Z7,"")) -> 1. 부양초등학교 2. 수택초등학교 3. 교문초등학교 | S7: =IF(초입!S7="","",""&초입!S7&IF(초입!W7<>"",CHAR(10)&""&초입!W7,"")&IF(초입!AA7<>"",CHAR(10)&""&초입!AA7,"")) -> 특수학급 특수학급 특수학급 | T7: =IF(초입!T7="","",""&초입!T7&IF(초입!X7<>"",CHAR(10)&""&초입!X7,"")&IF(초입!AB7<>"",CHAR(10)&""&초입!AB7,"")) | U7: =IF(초입!U7="","",""&초입!U7&IF(초입!Y7<>"",CHAR(10)&""&초입!Y7,"")&IF(초입!AC7<>"",CHAR(10)&""&초입!AC7,"")) -> 0.45 1.1 1.1 | V7: =IF(초입!AO7="","",초입!AO7) -> □ 복지카드: 자폐성장애 중증(~2032.01.14.) | W7: =IF(초입!AP7="","",초입!AP7) -> 도보 기준 작성함. 자동차기준, 교문1.2 / 토평1.1 / 수택 1.9 | X7: =IF(초입!AD7="","",초입!AD7) -> 010-3003-1574 | Y7: =IF(초입!AE7="","",초입!AE7) | Z7: =IF(초입!M7="","",초입!M7) -> 경기도 구리시 검배로72번길 89, 3층
A8: =초입!A8 -> 5 | B8: 초입 | C8: =IF(초입!H8<>"","O","") | D8: =IF(초입!I8<>"","O","") -> O | E8: =초입!B8 -> 시립토평마을어린이집 | F8: =IF(초입!C8="","",초입!C8) | G8: =IF(초입!D8="","",초입!D8) -> 3 | H8: =IF(초입!E8="","",초입!E8) -> 김서하 | I8: =IF(초입!F8="","",초입!F8) -> 남 | J8: =IF(초입!G8="","",초입!G8) -> 2020.07.15. | K8: =IF(초입!J8="","",초입!J8) -> 청각장애 | L8: =IF(초입!K8="","",초입!K8) -> 청각장애 | M8: =IF(초입!L8="","",초입!L8) -> 중증 | N8: =IF(초입!N8="","",초입!N8) -> 수택초등학교 | O8: =IF(초입!O8="","",초입!O8) -> 특수학급 | P8: =IF(초입!P8="","",초입!P8) | Q8: =IF(초입!Q8="","",초입!Q8) -> 0.237 | R8: =IF(초입!R8="","","1. "&초입!R8&IF(초입!V8<>"",CHAR(10)&"2. "&초입!V8,"")&IF(초입!Z8<>"",CHAR(10)&"3. "&초입!Z8,"")) -> 1. 수택초등학교 2. 수택초등학교 | S8: =IF(초입!S8="","",""&초입!S8&IF(초입!W8<>"",CHAR(10)&""&초입!W8,"")&IF(초입!AA8<>"",CHAR(10)&""&초입!AA8,"")) -> 특수학급 일반학급 | T8: =IF(초입!T8="","",""&초입!T8&IF(초입!X8<>"",CHAR(10)&""&초입!X8,"")&IF(초입!AB8<>"",CHAR(10)&""&초입!AB8,"")) | U8: =IF(초입!U8="","",""&초입!U8&IF(초입!Y8<>"",CHAR(10)&""&초입!Y8,"")&IF(초입!AC8<>"",CHAR(10)&""&초입!AC8,"")) -> 0.237 0.237 | V8: =IF(초입!AO8="","",초입!AO8) -> □ 복지카드: 청각장애 중증(유효기한 없음) | W8: =IF(초입!AP8="","",초입!AP8) -> 쌍둥이(김루하)와 동일교 배치 희망, 등본제출함 | X8: =IF(초입!AD8="","",초입!AD8) -> 010-9133-1701 | Y8: =IF(초입!AE8="","",초입!AE8) | Z8: =IF(초입!M8="","",초입!M8) -> 경기도 구리시 검배로 142 204동, 1104호(SK신일아파트)
A9: =초입!A9 -> 6 | B9: 초입 | C9: =IF(초입!H9<>"","O","") | D9: =IF(초입!I9<>"","O","") -> O | E9: =초입!B9 -> 시립토평마을어린이집 | F9: =IF(초입!C9="","",초입!C9) | G9: =IF(초입!D9="","",초입!D9) -> 3 | H9: =IF(초입!E9="","",초입!E9) -> 김루하 | I9: =IF(초입!F9="","",초입!F9) -> 남 | J9: =IF(초입!G9="","",초입!G9) -> 2020.07.15. | K9: =IF(초입!J9="","",초입!J9) -> 청각장애 | L9: =IF(초입!K9="","",초입!K9) -> 청각장애 | M9: =IF(초입!L9="","",초입!L9) -> 경증 | N9: =IF(초입!N9="","",초입!N9) -> 수택초등학교 | O9: =IF(초입!O9="","",초입!O9) -> 특수학급 | P9: =IF(초입!P9="","",초입!P9) | Q9: =IF(초입!Q9="","",초입!Q9) -> 0.237 | R9: =IF(초입!R9="","","1. "&초입!R9&IF(초입!V9<>"",CHAR(10)&"2. "&초입!V9,"")&IF(초입!Z9<>"",CHAR(10)&"3. "&초입!Z9,"")) -> 1. 수택초등학교 2. 수택초등학교 | S9: =IF(초입!S9="","",""&초입!S9&IF(초입!W9<>"",CHAR(10)&""&초입!W9,"")&IF(초입!AA9<>"",CHAR(10)&""&초입!AA9,"")) -> 특수학급 일반학급 | T9: =IF(초입!T9="","",""&초입!T9&IF(초입!X9<>"",CHAR(10)&""&초입!X9,"")&IF(초입!AB9<>"",CHAR(10)&""&초입!AB9,"")) | U9: =IF(초입!U9="","",""&초입!U9&IF(초입!Y9<>"",CHAR(10)&""&초입!Y9,"")&IF(초입!AC9<>"",CHAR(10)&""&초입!AC9,"")) -> 0.237 0.237 | V9: =IF(초입!AO9="","",초입!AO9) -> □ 복지카드: 청각장애 경증(~2028.07.28) | W9: =IF(초입!AP9="","",초입!AP9) -> 쌍둥이(김서하)와 동일교 배치 희망, 등본제출함 | X9: =IF(초입!AD9="","",초입!AD9) -> 010-9133-1701 | Y9: =IF(초입!AE9="","",초입!AE9) | Z9: =IF(초입!M9="","",초입!M9) -> 경기도 구리시 검배로 142 204동, 1104호(SK신일아파트)
A10: =초입!A10 -> 7 | B10: 초입 | C10: =IF(초입!H10<>"","O","") | D10: =IF(초입!I10<>"","O","") -> O | E10: =초입!B10 -> 화도어린이집 | F10: =IF(초입!C10="","",초입!C10) | G10: =IF(초입!D10="","",초입!D10) -> 3 | H10: =IF(초입!E10="","",초입!E10) -> 김로건 | I10: =IF(초입!F10="","",초입!F10) -> 남 | J10: =IF(초입!G10="","",초입!G10) -> 2020.10.12. | K10: =IF(초입!J10="","",초입!J10) -> 자폐성장애 | L10: =IF(초입!K10="","",초입!K10) -> 자폐성장애 | M10: =IF(초입!L10="","",초입!L10) -> 중증 | N10: =IF(초입!N10="","",초입!N10) -> 금남초등학교 | O10: =IF(초입!O10="","",초입!O10) -> 일반학급 | P10: =IF(초입!P10="","",초입!P10) | Q10: =IF(초입!Q10="","",초입!Q10) -> 0.05 | R10: =IF(초입!R10="","","1. "&초입!R10&IF(초입!V10<>"",CHAR(10)&"2. "&초입!V10,"")&IF(초입!Z10<>"",CHAR(10)&"3. "&초입!Z10,"")) -> 1. 금남초등학교 | S10: =IF(초입!S10="","",""&초입!S10&IF(초입!W10<>"",CHAR(10)&""&초입!W10,"")&IF(초입!AA10<>"",CHAR(10)&""&초입!AA10,"")) -> 일반학급 | T10: =IF(초입!T10="","",""&초입!T10&IF(초입!X10<>"",CHAR(10)&""&초입!X10,"")&IF(초입!AB10<>"",CHAR(10)&""&초입!AB10,"")) | U10: =IF(초입!U10="","",""&초입!U10&IF(초입!Y10<>"",CHAR(10)&""&초입!Y10,"")&IF(초입!AC10<>"",CHAR(10)&""&초입!AC10,"")) -> 0.05 | V10: =IF(초입!AO10="","",초입!AO10) -> □ 복지카드: 자폐성장애 중증(~2029.10.10.) | W10: =IF(초입!AP10="","",초입!AP10) | X10: =IF(초입!AD10="","",초입!AD10) -> 010-5350-1095 | Y10: =IF(초입!AE10="","",초입!AE10) | Z10: =IF(초입!M10="","",초입!M10) -> 경기도 남양주시 화도읍 북한강로 1503번길2, 2층
A11: =초입!A11 -> 8 | B11: 초입 | C11: =IF(초입!H11<>"","O","") | D11: =IF(초입!I11<>"","O","") -> O | E11: =초입!B11 -> 장현새싹어린이집 | F11: =IF(초입!C11="","",초입!C11) | G11: =IF(초입!D11="","",초입!D11) -> 3 | H11: =IF(초입!E11="","",초입!E11) -> 오태희 | I11: =IF(초입!F11="","",초입!F11) -> 여 | J11: =IF(초입!G11="","",초입!G11) -> 2020.04.17. | K11: =IF(초입!J11="","",초입!J11) -> 발달지체 | L11: =IF(초입!K11="","",초입!K11) | M11: =IF(초입!L11="","",초입!L11) | N11: =IF(초입!N11="","",초입!N11) -> 장현초등학교 | O11: =IF(초입!O11="","",초입!O11) -> 특수학급 | P11: =IF(초입!P11="","",초입!P11) | Q11: =IF(초입!Q11="","",초입!Q11) -> 0.1 | R11: =IF(초입!R11="","","1. "&초입!R11&IF(초입!V11<>"",CHAR(10)&"2. "&초입!V11,"")&IF(초입!Z11<>"",CHAR(10)&"3. "&초입!Z11,"")) -> 1. 장현초등학교 2. 장현초등학교 | S11: =IF(초입!S11="","",""&초입!S11&IF(초입!W11<>"",CHAR(10)&""&초입!W11,"")&IF(초입!AA11<>"",CHAR(10)&""&초입!AA11,"")) -> 특수학급 일반학급 | T11: =IF(초입!T11="","",""&초입!T11&IF(초입!X11<>"",CHAR(10)&""&초입!X11,"")&IF(초입!AB11<>"",CHAR(10)&""&초입!AB11,"")) | U11: =IF(초입!U11="","",""&초입!U11&IF(초입!Y11<>"",CHAR(10)&""&초입!Y11,"")&IF(초입!AC11<>"",CHAR(10)&""&초입!AC11,"")) -> 0.1 0.1 | V11: =IF(초입!AO11="","",초입!AO11) -> 진단평가 필요 | W11: =IF(초입!AP11="","",초입!AP11) | X11: =IF(초입!AD11="","",초입!AD11) -> 010-2895-1244 | Y11: =IF(초입!AE11="","",초입!AE11) | Z11: =IF(초입!M11="","",초입!M11) -> 경기도 남양주시 진접읍 장현로 87번길 9, 남양주택 라동 403호
A12: =초입!A12 -> 9 | B12: 초입 | C12: =IF(초입!H12<>"","O","") | D12: =IF(초입!I12<>"","O","") -> O | E12: =초입!B12 -> 구리시립갈매어린이집 | F12: =IF(초입!C12="","",초입!C12) | G12: =IF(초입!D12="","",초입!D12) -> 3 | H12: =IF(초입!E12="","",초입!E12) -> 이인규 | I12: =IF(초입!F12="","",초입!F12) -> 남 | J12: =IF(초입!G12="","",초입!G12) -> 2020.11.12. | K12: =IF(초입!J12="","",초입!J12) -> 의사소통장애 (지적장애 범주이나, 검사결과 신뢰X, 발달지체?, 심층관찰 시 자폐 성향) | L12: =IF(초입!K12="","",초입!K12) | M12: =IF(초입!L12="","",초입!L12) | N12: =IF(초입!N12="","",초입!N12) -> 퇴계원초등학교 | O12: =IF(초입!O12="","",초입!O12) -> 특수학급 | P12: =IF(초입!P12="","",초입!P12) | Q12: =IF(초입!Q12="","",초입!Q12) -> 1.1 | R12: =IF(초입!R12="","","1. "&초입!R12&IF(초입!V12<>"",CHAR(10)&"2. "&초입!V12,"")&IF(초입!Z12<>"",CHAR(10)&"3. "&초입!Z12,"")) -> 1. 퇴계원초등학교 2. 도제원초등학교 3. 내양초등학교 | S12: =IF(초입!S12="","",""&초입!S12&IF(초입!W12<>"",CHAR(10)&""&초입!W12,"")&IF(초입!AA12<>"",CHAR(10)&""&초입!AA12,"")) -> 특수학급 특수학급 특수학급 | T12: =IF(초입!T12="","",""&초입!T12&IF(초입!X12<>"",CHAR(10)&""&초입!X12,"")&IF(초입!AB12<>"",CHAR(10)&""&초입!AB12,"")) | U12: =IF(초입!U12="","",""&초입!U12&IF(초입!Y12<>"",CHAR(10)&""&초입!Y12,"")&IF(초입!AC12<>"",CHAR(10)&""&초입!AC12,"")) -> 1.1 1.1 2.4 | V12: =IF(초입!AO12="","",초입!AO12) -> ※2026년 7월 9일 검사 실시 □K-WPPSI-IV: 전체IQ 40 (언어이해 45, 시공간 79, 유동추론 45, 작업기억 45, 처리속도 45/매우 낮음) □적응행동검사: 표준점수 54(상당히 저조한 수준) □사회성숙도: SA 1세 11개월, SQ 35.30(중등도) | W12: =IF(초입!AP12="","",초입!AP12) | X12: =IF(초입!AD12="","",초입!AD12) -> 010-4397-1648 | Y12: =IF(초입!AE12="","",초입!AE12) | Z12: =IF(초입!M12="","",초입!M12) -> 경기도 남양주시 퇴계원읍 도제원로 89-1, 102동 301호(삼성하이츠)
A13: =초입!A13 -> 10 | B13: 초입 | C13: =IF(초입!H13<>"","O","") | D13: =IF(초입!I13<>"","O","") -> O | E13: =초입!B13 -> 다산아이사랑어린이집 | F13: =IF(초입!C13="","",초입!C13) | G13: =IF(초입!D13="","",초입!D13) -> 3 | H13: =IF(초입!E13="","",초입!E13) -> 정이안 | I13: =IF(초입!F13="","",초입!F13) -> 여 | J13: =IF(초입!G13="","",초입!G13) -> 2020.08.10. | K13: =IF(초입!J13="","",초입!J13) -> 자폐성장애 | L13: =IF(초입!K13="","",초입!K13) -> 발급중 | M13: =IF(초입!L13="","",초입!L13) | N13: =IF(초입!N13="","",초입!N13) -> 다산새봄초등학교 | O13: =IF(초입!O13="","",초입!O13) -> 특수학급 | P13: =IF(초입!P13="","",초입!P13) | Q13: =IF(초입!Q13="","",초입!Q13) -> 0.385 | R13: =IF(초입!R13="","","1. "&초입!R13&IF(초입!V13<>"",CHAR(10)&"2. "&초입!V13,"")&IF(초입!Z13<>"",CHAR(10)&"3. "&초입!Z13,"")) -> 1. 다산새봄초등학교 2. 다산가람초등학교 3. 남양주다산초등학교 | S13: =IF(초입!S13="","",""&초입!S13&IF(초입!W13<>"",CHAR(10)&""&초입!W13,"")&IF(초입!AA13<>"",CHAR(10)&""&초입!AA13,"")) -> 특수학급 특수학급 특수학급 | T13: =IF(초입!T13="","",""&초입!T13&IF(초입!X13<>"",CHAR(10)&""&초입!X13,"")&IF(초입!AB13<>"",CHAR(10)&""&초입!AB13,"")) | U13: =IF(초입!U13="","",""&초입!U13&IF(초입!Y13<>"",CHAR(10)&""&초입!Y13,"")&IF(초입!AC13<>"",CHAR(10)&""&초입!AC13,"")) -> 0.385 0.878 1.2 | V13: =IF(초입!AO13="","",초입!AO13) -> ※ 6월 중 복지카드 발급 예정 / 7월중말로 연기 | W13: =IF(초입!AP13="","",초입!AP13) -> *비장애 쌍둥이와 동일교 배치 희망 *2027년 1~2월 중 이사 예정, 그러나 이사 예정지와 입주일이 불명확하여 10월 말까지 계약서가 나오면 별도 연락주기로 함. | X13: =IF(초입!AD13="","",초입!AD13) -> 010-6641-1224 | Y13: =IF(초입!AE13="","",초입!AE13) | Z13: =IF(초입!M13="","",초입!M13) -> 경기도 남양주시 다산중앙로82번길 12, 5302동 2502호(다산자연앤 이편한세상 3차)
A14: =초입!A14 -> 11 | B14: 초입 | C14: =IF(초입!H14<>"","O","") | D14: =IF(초입!I14<>"","O","") -> O | E14: =초입!B14 -> 시립호평어린이집 | F14: =IF(초입!C14="","",초입!C14) | G14: =IF(초입!D14="","",초입!D14) -> 3 | H14: =IF(초입!E14="","",초입!E14) -> 김다원 | I14: =IF(초입!F14="","",초입!F14) -> 남 | J14: =IF(초입!G14="","",초입!G14) -> 2020.08.09. | K14: =IF(초입!J14="","",초입!J14) -> 청각장애 | L14: =IF(초입!K14="","",초입!K14) -> 청각장애 | M14: =IF(초입!L14="","",초입!L14) -> 중증 | N14: =IF(초입!N14="","",초입!N14) -> 남양주백봉초등학교 | O14: =IF(초입!O14="","",초입!O14) -> 특수학급 | P14: =IF(초입!P14="","",초입!P14) | Q14: =IF(초입!Q14="","",초입!Q14) -> 0.159 | R14: =IF(초입!R14="","","1. "&초입!R14&IF(초입!V14<>"",CHAR(10)&"2. "&초입!V14,"")&IF(초입!Z14<>"",CHAR(10)&"3. "&초입!Z14,"")) -> 1. 남양주백봉초등학교 2. 남양주백봉초등학교 | S14: =IF(초입!S14="","",""&초입!S14&IF(초입!W14<>"",CHAR(10)&""&초입!W14,"")&IF(초입!AA14<>"",CHAR(10)&""&초입!AA14,"")) -> 특수학급 일반학급 | T14: =IF(초입!T14="","",""&초입!T14&IF(초입!X14<>"",CHAR(10)&""&초입!X14,"")&IF(초입!AB14<>"",CHAR(10)&""&초입!AB14,"")) | U14: =IF(초입!U14="","",""&초입!U14&IF(초입!Y14<>"",CHAR(10)&""&초입!Y14,"")&IF(초입!AC14<>"",CHAR(10)&""&초입!AC14,"")) -> 0.159 0.159 | V14: =IF(초입!AO14="","",초입!AO14) -> □ 복지카드: 청각장애 중증(유효기한 없음) | W14: =IF(초입!AP14="","",초입!AP14) | X14: =IF(초입!AD14="","",초입!AD14) -> 010-9220-1146 | Y14: =IF(초입!AE14="","",초입!AE14) | Z14: =IF(초입!M14="","",초입!M14) -> 경기도 남양주시 평내로 104, 1905동 503호
A15: =초입!A15 -> 12 | B15: 초입 | C15: =IF(초입!H15<>"","O","") | D15: =IF(초입!I15<>"","O","") -> O | E15: =초입!B15 -> 하람어린이집 | F15: =IF(초입!C15="","",초입!C15) | G15: =IF(초입!D15="","",초입!D15) -> 3 | H15: =IF(초입!E15="","",초입!E15) -> 김하건 | I15: =IF(초입!F15="","",초입!F15) -> 남 | J15: =IF(초입!G15="","",초입!G15) -> 2020.07.16. | K15: =IF(초입!J15="","",초입!J15) -> 자폐성장애 | L15: =IF(초입!K15="","",초입!K15) -> 자폐성장애 | M15: =IF(초입!L15="","",초입!L15) -> 중증 | N15: =IF(초입!N15="","",초입!N15) -> 갈매초등학교 | O15: =IF(초입!O15="","",초입!O15) -> 특수학급 | P15: =IF(초입!P15="","",초입!P15) | Q15: =IF(초입!Q15="","",초입!Q15) -> 0.649 | R15: =IF(초입!R15="","","1. "&초입!R15&IF(초입!V15<>"",CHAR(10)&"2. "&초입!V15,"")&IF(초입!Z15<>"",CHAR(10)&"3. "&초입!Z15,"")) -> 1. 갈매초등학교 2. 산마루초등학교 3. 한별초등학교 | S15: =IF(초입!S15="","",""&초입!S15&IF(초입!W15<>"",CHAR(10)&""&초입!W15,"")&IF(초입!AA15<>"",CHAR(10)&""&초입!AA15,"")) -> 특수학급 특수학급 특수학급 | T15: =IF(초입!T15="","",""&초입!T15&IF(초입!X15<>"",CHAR(10)&""&초입!X15,"")&IF(초입!AB15<>"",CHAR(10)&""&초입!AB15,"")) | U15: =IF(초입!U15="","",""&초입!U15&IF(초입!Y15<>"",CHAR(10)&""&초입!Y15,"")&IF(초입!AC15<>"",CHAR(10)&""&초입!AC15,"")) -> 0.649 0.433 2.5 | V15: =IF(초입!AO15="","",초입!AO15) -> □ 복지카드: 자폐성장애 중증(~2029.06.21.) | W15: =IF(초입!AP15="","",초입!AP15) | X15: =IF(초입!AD15="","",초입!AD15) -> 010-4714-7728 | Y15: =IF(초입!AE15="","",초입!AE15) | Z15: =IF(초입!M15="","",초입!M15) -> 경기도 구리시 산마루로 46, 409동 1302호
... A101: =초입!A101 -> 98 | B101: 초입 | C101: =IF(초입!H101<>"","O","") -> O | D101: =IF(초입!I101<>"","O","") | E101: =초입!B101 -> 부평초등학교병설유치원 | F101: =IF(초입!C101="","",초입!C101) -> 특수학급 | G101: =IF(초입!D101="","",초입!D101) -> 3 | H101: =IF(초입!E101="","",초입!E101) -> 오하린 | I101: =IF(초입!F101="","",초입!F101) -> 여 | J101: =IF(초입!G101="","",초입!G101) -> 2020.09.09. | K101: =IF(초입!J101="","",초입!J101) -> 발달지체 | L101: =IF(초입!K101="","",초입!K101) | M101: =IF(초입!L101="","",초입!L101) | N101: =IF(초입!N101="","",초입!N101) -> 부평초등학교 | O101: =IF(초입!O101="","",초입!O101) -> 특수학급 | P101: =IF(초입!P101="","",초입!P101) | Q101: =IF(초입!Q101="","",초입!Q101) -> 0.353 | R101: =IF(초입!R101="","","1. "&초입!R101&IF(초입!V101<>"",CHAR(10)&"2. "&초입!V101,"")&IF(초입!Z101<>"",CHAR(10)&"3. "&초입!Z101,"")) -> 1. 부평초등학교 2. 장승초등학교 3. 광릉초등학교 | S101: =IF(초입!S101="","",""&초입!S101&IF(초입!W101<>"",CHAR(10)&""&초입!W101,"")&IF(초입!AA101<>"",CHAR(10)&""&초입!AA101,"")) -> 특수학급 특수학급 특수학급 | T101: =IF(초입!T101="","",""&초입!T101&IF(초입!X101<>"",CHAR(10)&""&초입!X101,"")&IF(초입!AB101<>"",CHAR(10)&""&초입!AB101,"")) | U101: =IF(초입!U101="","",""&초입!U101&IF(초입!Y101<>"",CHAR(10)&""&초입!Y101,"")&IF(초입!AC101<>"",CHAR(10)&""&초입!AC101,"")) -> 0.672 1.1 1.8 | V101: =IF(초입!AO101="","",초입!AO101) | W101: =IF(초입!AP101="","",초입!AP101) | X101: =IF(초입!AD101="","",초입!AD101) -> 010-4787-9057 | Y101: =IF(초입!AE101="","",초입!AE101) -> 김영미 | Z101: =IF(초입!M101="","",초입!M101) -> 경기도 남양주시 진접읍 부평로48번길 140, 105동 1501호(더샵퍼스트시티)

Sheet 초입 (특수학교)
A1: 연번 | B1: 구분 | C1: 선정배치 | E1: 소속교 | F1: 학급유형 | G1: 학년 | H1: 성명 | I1: 성별 | J1: 생년월일 | K1: 장애유형(유형변경 고려 필요) | N1: 희망교 | Q1: 검사결과 | R1: 특이사항 | S1: 연락처 | U1: 주소
C2: 기존 | D2: 신규 | K2: 특수교육법 | L2: 장애인복지법 | N2: 학교명 | O2: 지역 | P2: 학급유형
K3: 영역 | L3: 영역 | M3: 정도 | S3: 보호자 | T3: 담당교사
B4: 초입 | C4: =IF(초입!H4<>"","O","") | D4: =IF(초입!I4<>"","O","") -> O | E4: =초입!B4 -> 시립동구어린이집 | F4: =IF(초입!C4="","",초입!C4) | G4: =IF(초입!D4="","",초입!D4) -> 3 | H4: =IF(초입!E4="","",초입!E4) -> 김연성 | I4: =IF(초입!F4="","",초입!F4) -> 남 | J4: =IF(초입!G4="","",초입!G4) -> 2020.02.25. | K4: =IF(초입!J4="","",초입!J4) -> 의사소통장애 (지적장애 범주) | L4: =IF(초입!K4="","",초입!K4) | M4: =IF(초입!L4="","",초입!L4) | N4: =IF(초입!AF4="","","1. "&초입!AF4&IF(초입!AI4<>"",CHAR(10)&"2. "&초입!AI4,"")&IF(초입!AL4<>"",CHAR(10)&"3. "&초입!AL4,"")) | O4: =IF(초입!AG4="","",초입!AG4&IF(초입!AJ4<>"",CHAR(10)&초입!AJ4,"")&IF(초입!AM4<>"",CHAR(10)&초입!AM4,"")) | P4: =IF(초입!AH4="","",초입!AH4&IF(초입!AK4<>"",CHAR(10)&초입!AK4,"")&IF(초입!AN4<>"",CHAR(10)&초입!AN4,"")) | Q4: =IF(초입!AO4="","",초입!AO4) -> ※심리평가보고서(2026.3.12.) □ K-WPPSI-Ⅳ: 전체IQ 53(언어이해 50, 시공간 79, 유동추론 66, 작업기억 61, 처리속도 64/매우 낮음) □ 사회성숙도: SA 4세7개월, SQ 78.33(경계선) □ CARS: 22.5점 □ 적응행동검사: 표준점수 70(저조한 수준) | R4: =IF(초입!AP4="","",초입!AP4) -> *검사결과 지적장애 범주. 신규지만 지적장애로 유형변경 | S4: =IF(초입!AD4="","",초입!AD4) -> 010-8865-6065 | T4: =IF(초입!AE4="","",초입!AE4) | U4: =IF(초입!M4="","",초입!M4) -> 경기도 구리시 경춘로276번길 21, 107동 1002호(구리역한양수자인)
B5: 초입 | C5: =IF(초입!H5<>"","O","") | D5: =IF(초입!I5<>"","O","") -> O | E5: =초입!B5 -> 없음 | F5: =IF(초입!C5="","",초입!C5) | G5: =IF(초입!D5="","",초입!D5) | H5: =IF(초입!E5="","",초입!E5) -> 김주연 | I5: =IF(초입!F5="","",초입!F5) -> 여 | J5: =IF(초입!G5="","",초입!G5) -> 2020.10.10. | K5: =IF(초입!J5="","",초입!J5) -> 지적장애 | L5: =IF(초입!K5="","",초입!K5) -> 지적·자폐성장애 | M5: =IF(초입!L5="","",초입!L5) -> 중증 | N5: =IF(초입!AF5="","","1. "&초입!AF5&IF(초입!AI5<>"",CHAR(10)&"2. "&초입!AI5,"")&IF(초입!AL5<>"",CHAR(10)&"3. "&초입!AL5,"")) | O5: =IF(초입!AG5="","",초입!AG5&IF(초입!AJ5<>"",CHAR(10)&초입!AJ5,"")&IF(초입!AM5<>"",CHAR(10)&초입!AM5,"")) | P5: =IF(초입!AH5="","",초입!AH5&IF(초입!AK5<>"",CHAR(10)&초입!AK5,"")&IF(초입!AN5<>"",CHAR(10)&초입!AN5,"")) | Q5: =IF(초입!AO5="","",초입!AO5) -> □ 복지카드: 지적,자폐성장애 중증(~2032.03.02.) | R5: =IF(초입!AP5="","",초입!AP5) -> 7월30일 거주지 이전 / 대중교통 이용 / 현 주소 기준으로 거리 작성됨 / 자차기준 토평, 백문, 도림, 교문 모두 1.1~1.2km임 / 1순위 안되면 참고 | S5: =IF(초입!AD5="","",초입!AD5) -> 010-8999-2232 | T5: =IF(초입!AE5="","",초입!AE5) | U5: =IF(초입!M5="","",초입!M5) -> 현: 경기도 구리시 건원대로 92, 115동 1405호(인창동 주공아파트) 이사: 경기도 구리시 수택동 444-6
A6: =SUBTOTAL(103,$N$6:N6) -> 1 | B6: 초입 | C6: =IF(초입!H6<>"","O","") | D6: =IF(초입!I6<>"","O","") -> O | E6: =초입!B6 -> 하늘숲어린이집 | F6: =IF(초입!C6="","",초입!C6) | G6: =IF(초입!D6="","",초입!D6) -> 3 | H6: =IF(초입!E6="","",초입!E6) -> 양서율 | I6: =IF(초입!F6="","",초입!F6) -> 여 | J6: =IF(초입!G6="","",초입!G6) -> 2020.01.26. | K6: =IF(초입!J6="","",초입!J6) -> 자폐성장애 | L6: =IF(초입!K6="","",초입!K6) -> 자폐성장애 | M6: =IF(초입!L6="","",초입!L6) -> 중증 | N6: =IF(초입!AG6="","","1. "&초입!AG6&IF(초입!AJ6<>"",CHAR(10)&"2. "&초입!AJ6,"")&IF(초입!AM6<>"",CHAR(10)&"3. "&초입!AM6,"")) -> 1. 경은학교 2. 복합특수학급 신설 3. 송민학교 | O6: =IF(초입!AF6="","",초입!AF6&IF(초입!AI6<>"",CHAR(10)&초입!AI6,"")&IF(초입!AL6<>"",CHAR(10)&초입!AL6,"")) -> 구리남양주 구리남양주 의정부 | P6: =IF(초입!AH6="","",초입!AH6&IF(초입!AK6<>"",CHAR(10)&초입!AK6,"")&IF(초입!AN6<>"",CHAR(10)&초입!AN6,"")) -> 특수학교 복합특수학급 특수학교 | Q6: =IF(초입!AO6="","",초입!AO6) -> □ 복지카드: 자폐성장애 중증(~2028.09.28.) | R6: =IF(초입!AP6="","",초입!AP6) | S6: =IF(초입!AD6="","",초입!AD6) -> 010-2228-7151 | T6: =IF(초입!AE6="","",초입!AE6) | U6: =IF(초입!M6="","",초입!M6) -> 경기도 남양주시 오남읍 양지로46번길 130, 102동 503호
B7: 초입 | C7: =IF(초입!H7<>"","O","") | D7: =IF(초입!I7<>"","O","") -> O | E7: =초입!B7 -> 시립토평마을어린이집 | F7: =IF(초입!C7="","",초입!C7) | G7: =IF(초입!D7="","",초입!D7) -> 3 | H7: =IF(초입!E7="","",초입!E7) -> 신주원 | I7: =IF(초입!F7="","",초입!F7) -> 남 | J7: =IF(초입!G7="","",초입!G7) -> 2020.08.16. | K7: =IF(초입!J7="","",초입!J7) -> 자폐성장애 | L7: =IF(초입!K7="","",초입!K7) -> 자폐성장애 | M7: =IF(초입!L7="","",초입!L7) -> 중증 | N7: =IF(초입!AF7="","","1. "&초입!AF7&IF(초입!AI7<>"",CHAR(10)&"2. "&초입!AI7,"")&IF(초입!AL7<>"",CHAR(10)&"3. "&초입!AL7,"")) | O7: =IF(초입!AG7="","",초입!AG7&IF(초입!AJ7<>"",CHAR(10)&초입!AJ7,"")&IF(초입!AM7<>"",CHAR(10)&초입!AM7,"")) | P7: =IF(초입!AH7="","",초입!AH7&IF(초입!AK7<>"",CHAR(10)&초입!AK7,"")&IF(초입!AN7<>"",CHAR(10)&초입!AN7,"")) | Q7: =IF(초입!AO7="","",초입!AO7) -> □ 복지카드: 자폐성장애 중증(~2032.01.14.) | R7: =IF(초입!AP7="","",초입!AP7) -> 도보 기준 작성함. 자동차기준, 교문1.2 / 토평1.1 / 수택 1.9 | S7: =IF(초입!AD7="","",초입!AD7) -> 010-3003-1574 | T7: =IF(초입!AE7="","",초입!AE7) | U7: =IF(초입!M7="","",초입!M7) -> 경기도 구리시 검배로72번길 89, 3층
B8: 초입 | C8: =IF(초입!H8<>"","O","") | D8: =IF(초입!I8<>"","O","") -> O | E8: =초입!B8 -> 시립토평마을어린이집 | F8: =IF(초입!C8="","",초입!C8) | G8: =IF(초입!D8="","",초입!D8) -> 3 | H8: =IF(초입!E8="","",초입!E8) -> 김서하 | I8: =IF(초입!F8="","",초입!F8) -> 남 | J8: =IF(초입!G8="","",초입!G8) -> 2020.07.15. | K8: =IF(초입!J8="","",초입!J8) -> 청각장애 | L8: =IF(초입!K8="","",초입!K8) -> 청각장애 | M8: =IF(초입!L8="","",초입!L8) -> 중증 | N8: =IF(초입!AF8="","","1. "&초입!AF8&IF(초입!AI8<>"",CHAR(10)&"2. "&초입!AI8,"")&IF(초입!AL8<>"",CHAR(10)&"3. "&초입!AL8,"")) | O8: =IF(초입!AG8="","",초입!AG8&IF(초입!AJ8<>"",CHAR(10)&초입!AJ8,"")&IF(초입!AM8<>"",CHAR(10)&초입!AM8,"")) | P8: =IF(초입!AH8="","",초입!AH8&IF(초입!AK8<>"",CHAR(10)&초입!AK8,"")&IF(초입!AN8<>"",CHAR(10)&초입!AN8,"")) | Q8: =IF(초입!AO8="","",초입!AO8) -> □ 복지카드: 청각장애 중증(유효기한 없음) | R8: =IF(초입!AP8="","",초입!AP8) -> 쌍둥이(김루하)와 동일교 배치 희망, 등본제출함 | S8: =IF(초입!AD8="","",초입!AD8) -> 010-9133-1701 | T8: =IF(초입!AE8="","",초입!AE8) | U8: =IF(초입!M8="","",초입!M8) -> 경기도 구리시 검배로 142 204동, 1104호(SK신일아파트)
B9: 초입 | C9: =IF(초입!H9<>"","O","") | D9: =IF(초입!I9<>"","O","") -> O | E9: =초입!B9 -> 시립토평마을어린이집 | F9: =IF(초입!C9="","",초입!C9) | G9: =IF(초입!D9="","",초입!D9) -> 3 | H9: =IF(초입!E9="","",초입!E9) -> 김루하 | I9: =IF(초입!F9="","",초입!F9) -> 남 | J9: =IF(초입!G9="","",초입!G9) -> 2020.07.15. | K9: =IF(초입!J9="","",초입!J9) -> 청각장애 | L9: =IF(초입!K9="","",초입!K9) -> 청각장애 | M9: =IF(초입!L9="","",초입!L9) -> 경증 | N9: =IF(초입!AF9="","","1. "&초입!AF9&IF(초입!AI9<>"",CHAR(10)&"2. "&초입!AI9,"")&IF(초입!AL9<>"",CHAR(10)&"3. "&초입!AL9,"")) | O9: =IF(초입!AG9="","",초입!AG9&IF(초입!AJ9<>"",CHAR(10)&초입!AJ9,"")&IF(초입!AM9<>"",CHAR(10)&초입!AM9,"")) | P9: =IF(초입!AH9="","",초입!AH9&IF(초입!AK9<>"",CHAR(10)&초입!AK9,"")&IF(초입!AN9<>"",CHAR(10)&초입!AN9,"")) | Q9: =IF(초입!AO9="","",초입!AO9) -> □ 복지카드: 청각장애 경증(~2028.07.28) | R9: =IF(초입!AP9="","",초입!AP9) -> 쌍둥이(김서하)와 동일교 배치 희망, 등본제출함 | S9: =IF(초입!AD9="","",초입!AD9) -> 010-9133-1701 | T9: =IF(초입!AE9="","",초입!AE9) | U9: =IF(초입!M9="","",초입!M9) -> 경기도 구리시 검배로 142 204동, 1104호(SK신일아파트)
B10: 초입 | C10: =IF(초입!H10<>"","O","") | D10: =IF(초입!I10<>"","O","") -> O | E10: =초입!B10 -> 화도어린이집 | F10: =IF(초입!C10="","",초입!C10) | G10: =IF(초입!D10="","",초입!D10) -> 3 | H10: =IF(초입!E10="","",초입!E10) -> 김로건 | I10: =IF(초입!F10="","",초입!F10) -> 남 | J10: =IF(초입!G10="","",초입!G10) -> 2020.10.12. | K10: =IF(초입!J10="","",초입!J10) -> 자폐성장애 | L10: =IF(초입!K10="","",초입!K10) -> 자폐성장애 | M10: =IF(초입!L10="","",초입!L10) -> 중증 | N10: =IF(초입!AF10="","","1. "&초입!AF10&IF(초입!AI10<>"",CHAR(10)&"2. "&초입!AI10,"")&IF(초입!AL10<>"",CHAR(10)&"3. "&초입!AL10,"")) | O10: =IF(초입!AG10="","",초입!AG10&IF(초입!AJ10<>"",CHAR(10)&초입!AJ10,"")&IF(초입!AM10<>"",CHAR(10)&초입!AM10,"")) | P10: =IF(초입!AH10="","",초입!AH10&IF(초입!AK10<>"",CHAR(10)&초입!AK10,"")&IF(초입!AN10<>"",CHAR(10)&초입!AN10,"")) | Q10: =IF(초입!AO10="","",초입!AO10) -> □ 복지카드: 자폐성장애 중증(~2029.10.10.) | R10: =IF(초입!AP10="","",초입!AP10) | S10: =IF(초입!AD10="","",초입!AD10) -> 010-5350-1095 | T10: =IF(초입!AE10="","",초입!AE10) | U10: =IF(초입!M10="","",초입!M10) -> 경기도 남양주시 화도읍 북한강로 1503번길2, 2층
